Workbook
Name Acq_Fee_Pct: Overview!$F$32
Name Acquisition_Price: Overview!$C$14
Name Addl_Income: Overview!$C$28
Name AM_Fee_Pct: Overview!$F$33
Name Amort1_Years: Overview!$F$16
Name Assessed_Value: Overview!$C$26
Name Close_Date: Overview!$C$6
Name Closing_Cost_Pct: Overview!$C$15
Name Credit_Loss_Pct: Overview!$C$21
Name Default_Downtime: Overview!$F$8
Name Default_Renewal_Prob: Overview!$F$9
Name Exit_Cap: Overview!$C$18
Name Exit_Month: Overview!$C$19
Name IO1_Months: Overview!$F$15
Name LC_New: Overview!$F$6
Name LC_Renewal: Overview!$F$7
Name Legal_Monthly: Overview!$F$34
Name Loan1_Amount: Overview!$F$13
Name Mgmt_Fee_Pct: Overview!$C$27
Name Millage_Rate: Overview!$C$24
Name Monthly_OpEx: 'OM OpEx'!$G$21
Name NRA: Overview!$C$7
Name opex_annual_growth: Overview!$C$25
Name opex_no_pm: 'OM OpEx'!$G$21
Name Orig_Fee1: Overview!$F$18
Name Rate1: Overview!$F$14
Name Refi_Amort: Overview!$F$27
Name Refi_IO: Overview!$F$26
Name Refi_Loan_Amt: Overview!$F$24
Name Refi_LTV: Overview!$F$23
Name Refi_Month: Overview!$F$22
Name Refi_Orig_Fee: Overview!$F$29
Name Refi_Rate: Overview!$F$25
Name Refi_Term: Overview!$F$28
Name Refi_Toggle: Overview!$F$21
Name Rent_Growth: Overview!$C$23
Name Repl_Reserve_PSF: Overview!$C$22
Name Selling_Cost_Pct: Overview!$C$20
Name Term1_Months: Overview!$F$17
Name TI_New: Overview!$F$4
Name TI_Renewal: Overview!$F$5

Sheet Monthly CF
A1: MONTHLY CASH FLOW
B2: Month | C2: 1 | D2: 2 | E2: 3 | F2: 4 | G2: 5 | H2: 6 | I2: 7 | J2: 8 | K2: 9 | L2: 10 | M2: 11 | N2: 12 | O2: 13 | P2: 14 | Q2: 15 | R2: 16 | S2: 17 | T2: 18 | U2: 19 | V2: 20 | W2: 21 | X2: 22 | Y2: 23 | Z2: 24 | AA2: 25 | AB2: 26 | AC2: 27 | AD2: 28 | AE2: 29 | AF2: 30 | AG2: 31 | AH2: 32 | AI2: 33 | AJ2: 34 | AK2: 35 | AL2: 36 | AM2: 37 | AN2: 38 | AO2: 39 | AP2: 40 | AQ2: 41 | AR2: 42 | AS2: 43 | AT2: 44 | AU2: 45 | AV2: 46 | AW2: 47 | AX2: 48 | AY2: 49 | AZ2: 50 | BA2: 51 | BB2: 52 | BC2: 53 | BD2: 54 | BE2: 55 | BF2: 56 | BG2: 57 | BH2: 58 | BI2: 59 | BJ2: 60
B3: Year | C3: =INT((C2-1)/12)+1 -> 1 | D3: =INT((D2-1)/12)+1 -> 1 | E3: =INT((E2-1)/12)+1 -> 1 | F3: =INT((F2-1)/12)+1 -> 1 | G3: =INT((G2-1)/12)+1 -> 1 | H3: =INT((H2-1)/12)+1 -> 1 | I3: =INT((I2-1)/12)+1 -> 1 | J3: =INT((J2-1)/12)+1 -> 1 | ... BJ3: =INT((BJ2-1)/12)+1 -> 5
B4: Date | C4: =EDATE(Close_Date,C2-1) -> 46143 | D4: =EDATE(Close_Date,D2-1) -> 46174 | E4: =EDATE(Close_Date,E2-1) -> 46204 | F4: =EDATE(Close_Date,F2-1) -> 46235 | G4: =EDATE(Close_Date,G2-1) -> 46266 | H4: =EDATE(Close_Date,H2-1) -> 46296 | I4: =EDATE(Close_Date,I2-1) -> 46327 | J4: =EDATE(Close_Date,J2-1) -> 46357 | ... BJ4: =EDATE(Close_Date,BJ2-1) -> 47939
B6: INCOME
B7: Total Collected Rent | C7: ='Rent Roll'!V44 -> 14111.5 | D7: ='Rent Roll'!W44 -> 14111.5 | E7: ='Rent Roll'!X44 -> 14111.5 | F7: ='Rent Roll'!Y44 -> 14111.5 | G7: ='Rent Roll'!Z44 -> 14111.5 | H7: ='Rent Roll'!AA44 -> 16371.5 | I7: ='Rent Roll'!AB44 -> 19014 | J7: ='Rent Roll'!AC44 -> 19014 | ... BJ7: ='Rent Roll'!CC44 -> 20124.098
B8: Additional Income | C8: =Addl_Income -> 1376.0833 | D8: =Addl_Income -> 1376.0833 | E8: =Addl_Income -> 1376.0833 | F8: =Addl_Income -> 1376.0833 | G8: =Addl_Income -> 1376.0833 | H8: =Addl_Income -> 1376.0833 | I8: =Addl_Income -> 1376.0833 | J8: =Addl_Income -> 1376.0833 | ... BJ8: =Addl_Income -> 1376.0833
B9: Gross Income | C9: =SUM(C7:C8) -> 15487.583 | D9: =SUM(D7:D8) -> 15487.583 | E9: =SUM(E7:E8) -> 15487.583 | F9: =SUM(F7:F8) -> 15487.583 | G9: =SUM(G7:G8) -> 15487.583 | H9: =SUM(H7:H8) -> 17747.583 | I9: =SUM(I7:I8) -> 20390.083 | J9: =SUM(J7:J8) -> 20390.083 | ... BJ9: =SUM(BJ7:BJ8) -> 21500.181
B10: Credit Loss | C10: =-Credit_Loss_Pct*C9 -> -774.37917 | D10: =-Credit_Loss_Pct*D9 -> -774.37917 | E10: =-Credit_Loss_Pct*E9 -> -774.37917 | F10: =-Credit_Loss_Pct*F9 -> -774.37917 | G10: =-Credit_Loss_Pct*G9 -> -774.37917 | H10: =-Credit_Loss_Pct*H9 -> -887.37917 | I10: =-Credit_Loss_Pct*I9 -> -1019.5042 | J10: =-Credit_Loss_Pct*J9 -> -1019.5042 | ... BJ10: =-Credit_Loss_Pct*BJ9 -> -1075.009
B11: Effective Gross Income (EGI) | C11: =C9+C10 -> 14713.204 | D11: =D9+D10 -> 14713.204 | E11: =E9+E10 -> 14713.204 | F11: =F9+F10 -> 14713.204 | G11: =G9+G10 -> 14713.204 | H11: =H9+H10 -> 16860.204 | I11: =I9+I10 -> 19370.579 | J11: =J9+J10 -> 19370.579 | ... BJ11: =BJ9+BJ10 -> 20425.172
B13: Reimbursement Income | C13: ='Rent Roll'!V45 -> 10950.016 | D13: ='Rent Roll'!W45 -> 10967.422 | E13: ='Rent Roll'!X45 -> 10984.857 | F13: ='Rent Roll'!Y45 -> 11002.32 | G13: ='Rent Roll'!Z45 -> 11019.813 | H13: ='Rent Roll'!AA45 -> 13106.104 | I13: ='Rent Roll'!AB45 -> 16018.2 | J13: ='Rent Roll'!AC45 -> 16043.376 | ... BJ13: ='Rent Roll'!CC45 -> 17453.634
B15: EGI + REIMBURSEMEBNTS | C15: =C13 + C11 -> 25663.22 | D15: =D13 + D11 -> 25680.626 | E15: =E13 + E11 -> 25698.061 | F15: =F13 + F11 -> 25715.525 | G15: =G13 + G11 -> 25733.017 | H15: =H13 + H11 -> 29966.308 | I15: =I13 + I11 -> 35388.78 | J15: =J13 + J11 -> 35413.955 | ... BJ15: =BJ13 + BJ11 -> 37878.806
B17: OPERATING EXPENSES
B18: Total Operating Expenses | C18: =Monthly_OpEx -> 15093.193 | D18: =C18*(1 + Overview!$C$25)^(1/12) -> 15118.12 | E18: =D18*(1 + Overview!$C$25)^(1/12) -> 15143.089 | F18: =E18*(1 + Overview!$C$25)^(1/12) -> 15168.099 | G18: =F18*(1 + Overview!$C$25)^(1/12) -> 15193.15 | H18: =G18*(1 + Overview!$C$25)^(1/12) -> 15218.243 | I18: =H18*(1 + Overview!$C$25)^(1/12) -> 15243.377 | J18: =I18*(1 + Overview!$C$25)^(1/12) -> 15268.553 | K18: =J18*(1 + Overview!$C$25)^(1/12) -> 15293.77 | ... BJ18: =BI18*(1 + Overview!$C$25)^(1/12) -> 16636.627
B19: Property Management Fee | C19: =Mgmt_Fee_Pct*C11 -> 588.52817 | D19: =Mgmt_Fee_Pct*D11 -> 588.52817 | E19: =Mgmt_Fee_Pct*E11 -> 588.52817 | F19: =Mgmt_Fee_Pct*F11 -> 588.52817 | G19: =Mgmt_Fee_Pct*G11 -> 588.52817 | H19: =Mgmt_Fee_Pct*H11 -> 674.40817 | I19: =Mgmt_Fee_Pct*I11 -> 774.82317 | J19: =Mgmt_Fee_Pct*J11 -> 774.82317 | ... BJ19: =Mgmt_Fee_Pct*BJ11 -> 817.00687
B20: Total Expenses | C20: =C18+C19 -> 15681.721 | D20: =D18+D19 -> 15706.648 | E20: =E18+E19 -> 15731.617 | F20: =F18+F19 -> 15756.627 | G20: =G18+G19 -> 15781.678 | H20: =H18+H19 -> 15892.651 | I20: =I18+I19 -> 16018.2 | J20: =J18+J19 -> 16043.376 | ... BJ20: =BJ18+BJ19 -> 17453.634
B22: NET OPERATING INCOME (NOI) | C22: =C15-C20 -> 9981.4993 | D22: =D15-D20 -> 9973.9778 | E22: =E15-E20 -> 9966.4439 | F22: =F15-F20 -> 9958.8975 | G22: =G15-G20 -> 9951.3386 | H22: =H15-H20 -> 14073.657 | I22: =I15-I20 -> 19370.579 | J22: =J15-J20 -> 19370.579 | ... BJ22: =BJ15-BJ20 -> 20425.172
B24: BELOW-THE-LINE
B25: CapEx | C25: =-'CapEx & TI-LC'!H13 -> -25000 | D25: =-'CapEx & TI-LC'!I13 -> -25000 | E25: =-'CapEx & TI-LC'!J13 -> -25000 | F25: =-'CapEx & TI-LC'!K13 -> -25000 | G25: =-'CapEx & TI-LC'!L13 -> -25000 | H25: =-'CapEx & TI-LC'!M13 -> -25000 | I25: =-'CapEx & TI-LC'!N13 -> 0 | J25: =-'CapEx & TI-LC'!O13 -> 0 | ... BJ25: =-'CapEx & TI-LC'!BO13 -> 0
B26: Tenant Improvements | C26: =-'CapEx & TI-LC'!H30 -> 0 | D26: =-'CapEx & TI-LC'!I30 -> 0 | E26: =-'CapEx & TI-LC'!J30 -> 0 | F26: =-'CapEx & TI-LC'!K30 -> 0 | G26: =-'CapEx & TI-LC'!L30 -> 0 | H26: =-'CapEx & TI-LC'!M30 -> -56500 | I26: =-'CapEx & TI-LC'!N30 -> -98100 | J26: =-'CapEx & TI-LC'!O30 -> 0 | ... BJ26: =-'CapEx & TI-LC'!BO30 -> -36200
B27: Leasing Commissions | C27: =-'CapEx & TI-LC'!H46 -> 0 | D27: =-'CapEx & TI-LC'!I46 -> 0 | E27: =-'CapEx & TI-LC'!J46 -> 0 | F27: =-'CapEx & TI-LC'!K46 -> 0 | G27: =-'CapEx & TI-LC'!L46 -> 0 | H27: =-'CapEx & TI-LC'!M46 -> -8136 | I27: =-'CapEx & TI-LC'!N46 -> -18387 | J27: =-'CapEx & TI-LC'!O46 -> 0 | ... BJ27: =-'CapEx & TI-LC'!BO46 -> -9167.2693
B28: Total Capex, LI, LC | C28: =SUM(C25:C27) -> -25000 | D28: =SUM(D25:D27) -> -25000 | E28: =SUM(E25:E27) -> -25000 | F28: =SUM(F25:F27) -> -25000 | G28: =SUM(G25:G27) -> -25000 | H28: =SUM(H25:H27) -> -89636 | I28: =SUM(I25:I27) -> -116487 | J28: =SUM(J25:J27) -> 0 | ... BJ28: =SUM(BJ25:BJ27) -> -45367.269
B29: Cash Flow Before Debt Service | C29: =C22+C25+C26+C27 -> -15018.501 | D29: =D22+D25+D26+D27 -> -15026.022 | E29: =E22+E25+E26+E27 -> -15033.556 | F29: =F22+F25+F26+F27 -> -15041.103 | G29: =G22+G25+G26+G27 -> -15048.661 | H29: =H22+H25+H26+H27 -> -75562.343 | I29: =I22+I25+I26+I27 -> -97116.421 | J29: =J22+J25+J26+J27 -> 19370.579 | ... BJ29: =BJ22+BJ25+BJ26+BJ27 -> -24942.097
B31: DEBT SERVICE & OTHER
B32: Total Debt Service | C32: =-Debt!C23 -> -11666.667 | D32: =-Debt!D23 -> -11666.667 | E32: =-Debt!E23 -> -11666.667 | F32: =-Debt!F23 -> -11666.667 | G32: =-Debt!G23 -> -11666.667 | H32: =-Debt!H23 -> -11666.667 | I32: =-Debt!I23 -> -11666.667 | J32: =-Debt!J23 -> -11666.667 | ... BJ32: =-Debt!BJ23 -> -14701.247
B33: Replacement Reserve | C33: =-Repl_Reserve_PSF*NRA/12 -> -745 | D33: =-Repl_Reserve_PSF*NRA/12 -> -745 | E33: =-Repl_Reserve_PSF*NRA/12 -> -745 | F33: =-Repl_Reserve_PSF*NRA/12 -> -745 | G33: =-Repl_Reserve_PSF*NRA/12 -> -745 | H33: =-Repl_Reserve_PSF*NRA/12 -> -745 | I33: =-Repl_Reserve_PSF*NRA/12 -> -745 | J33: =-Repl_Reserve_PSF*NRA/12 -> -745 | ... BJ33: =-Repl_Reserve_PSF*NRA/12 -> -745
B34: Acquisition Fee | C34: 0 | D34: 0 | E34: 0 | F34: 0 | G34: 0 | H34: 0 | I34: 0 | J34: 0 | K34: 0 | L34: 0 | M34: 0 | N34: 0 | O34: 0 | P34: 0 | Q34: 0 | R34: 0 | S34: 0 | T34: 0 | U34: 0 | V34: 0 | W34: 0 | X34: 0 | Y34: 0 | Z34: 0 | AA34: 0 | AB34: 0 | AC34: 0 | AD34: 0 | AE34: 0 | AF34: 0 | AG34: 0 | AH34: 0 | AI34: 0 | AJ34: 0 | AK34: 0 | AL34: 0 | AM34: 0 | AN34: 0 | AO34: 0 | AP34: 0 | AQ34: 0 | AR34: 0 | AS34: 0 | AT34: 0 | AU34: 0 | AV34: 0 | AW34: 0 | AX34: 0 | AY34: 0 | AZ34: 0 | BA34: 0 | BB34: 0 | BC34: 0 | BD34: 0 | BE34: 0 | BF34: 0 | BG34: 0 | BH34: 0 | BI34: 0 | BJ34: 0
B35: Asset Management Fee | C35: =-AM_Fee_Pct*Overview!$L$10 / 12 -> -823.33333 | D35: =-AM_Fee_Pct*Overview!$L$10 / 12 -> -823.33333 | E35: =-AM_Fee_Pct*Overview!$L$10 / 12 -> -823.33333 | F35: =-AM_Fee_Pct*Overview!$L$10 / 12 -> -823.33333 | G35: =-AM_Fee_Pct*Overview!$L$10 / 12 -> -823.33333 | H35: =-AM_Fee_Pct*Overview!$L$10 / 12 -> -823.33333 | I35: =-AM_Fee_Pct*Overview!$L$10 / 12 -> -823.33333 | J35: =-AM_Fee_Pct*Overview!$L$10 / 12 -> -823.33333 | ... BJ35: =-AM_Fee_Pct*Overview!$L$10 / 12 -> -823.33333
B36: Legal/Acct/Banking | C36: =-Legal_Monthly -> -500 | D36: =-Legal_Monthly -> -500 | E36: =-Legal_Monthly -> -500 | F36: =-Legal_Monthly -> -500 | G36: =-Legal_Monthly -> -500 | H36: =-Legal_Monthly -> -500 | I36: =-Legal_Monthly -> -500 | J36: =-Legal_Monthly -> -500 | ... BJ36: =-Legal_Monthly -> -500
B38: CASH AVAILABLE FOR DISTRIBUTION | C38: =C29+C32+C33+C34+C35+C36 -> -28753.501 | D38: =D29+D32+D33+D34+D35+D36 -> -28761.022 | E38: =E29+E32+E33+E34+E35+E36 -> -28768.556 | F38: =F29+F32+F33+F34+F35+F36 -> -28776.103 | G38: =G29+G32+G33+G34+G35+G36 -> -28783.661 | H38: =H29+H32+H33+H34+H35+H36 -> -89297.343 | I38: =I29+I32+I33+I34+I35+I36 -> -110851.42 | J38: =J29+J32+J33+J34+J35+J36 -> 5635.5792 | ... BJ38: =BJ29+BJ32+BJ33+BJ34+BJ35+BJ36 -> -41711.678
B40: Net Refi Proceeds | C40: =Debt!C24 -> 0 | D40: =Debt!D24 -> 0 | E40: =Debt!E24 -> 0 | F40: =Debt!F24 -> 0 | G40: =Debt!G24 -> 0 | H40: =Debt!H24 -> 0 | I40: =Debt!I24 -> 0 | J40: =Debt!J24 -> 0 | ... BJ40: =Debt!BJ24 -> 0
B42: SALE / DISPOSITION
B43: T12 NOI (at exit) | C43: =IF(C2=Exit_Month,C22*12,0) -> 0 | D43: =IF(D2=Exit_Month,D22*12,0) -> 0 | E43: =IF(E2=Exit_Month,E22*12,0) -> 0 | F43: =IF(F2=Exit_Month,F22*12,0) -> 0 | G43: =IF(G2=Exit_Month,G22*12,0) -> 0 | H43: =IF(H2=Exit_Month,H22*12,0) -> 0 | I43: =IF(I2=Exit_Month,I22*12,0) -> 0 | J43: =IF(J2=Exit_Month,J22*12,0) -> 0 | ... BJ43: =IF(BJ2=Exit_Month,BJ22*12,0) -> 245102.06
B44: Gross Sale Price | C44: =IF(C2=Exit_Month,C43/Exit_Cap,0) -> 0 | D44: =IF(D2=Exit_Month,D43/Exit_Cap,0) -> 0 | E44: =IF(E2=Exit_Month,E43/Exit_Cap,0) -> 0 | F44: =IF(F2=Exit_Month,F43/Exit_Cap,0) -> 0 | G44: =IF(G2=Exit_Month,G43/Exit_Cap,0) -> 0 | H44: =IF(H2=Exit_Month,H43/Exit_Cap,0) -> 0 | I44: =IF(I2=Exit_Month,I43/Exit_Cap,0) -> 0 | J44: =IF(J2=Exit_Month,J43/Exit_Cap,0) -> 0 | ... BJ44: =IF(BJ2=Exit_Month,BJ43/Exit_Cap,0) -> 3063775.8
B45: Less: Selling Costs | C45: =IF(C2=Exit_Month,-Selling_Cost_Pct*C44,0) -> 0 | D45: =IF(D2=Exit_Month,-Selling_Cost_Pct*D44,0) -> 0 | E45: =IF(E2=Exit_Month,-Selling_Cost_Pct*E44,0) -> 0 | F45: =IF(F2=Exit_Month,-Selling_Cost_Pct*F44,0) -> 0 | G45: =IF(G2=Exit_Month,-Selling_Cost_Pct*G44,0) -> 0 | H45: =IF(H2=Exit_Month,-Selling_Cost_Pct*H44,0) -> 0 | I45: =IF(I2=Exit_Month,-Selling_Cost_Pct*I44,0) -> 0 | J45: =IF(J2=Exit_Month,-Selling_Cost_Pct*J44,0) -> 0 | ... BJ45: =IF(BJ2=Exit_Month,-Selling_Cost_Pct*BJ44,0) -> -61275.515
B46: Less: Loan Payoff | C46: =-Debt!C25 -> 0 | D46: =-Debt!D25 -> 0 | E46: =-Debt!E25 -> 0 | F46: =-Debt!F25 -> 0 | G46: =-Debt!G25 -> 0 | H46: =-Debt!H25 -> 0 | I46: =-Debt!I25 -> 0 | J46: =-Debt!J25 -> 0 | ... BJ46: =-Debt!BJ25 -> -1896785.5
B47: Net Sale Proceeds to Equity | C47: =C44+C45+C46 -> 0 | D47: =D44+D45+D46 -> 0 | E47: =E44+E45+E46 -> 0 | F47: =F44+F45+F46 -> 0 | G47: =G44+G45+G46 -> 0 | H47: =H44+H45+H46 -> 0 | I47: =I44+I45+I46 -> 0 | J47: =J44+J45+J46 -> 0 | ... BJ47: =BJ44+BJ45+BJ46 -> 1105714.8
B49: RETURN CALCULATIONS
B50: Equity Investment | C50: =IF(C2=1,-(Overview!I20-Overview!I6),0) -> -988000 | D50: =IF(D2=1,-(Overview!J20-Overview!J6),0) -> 0 | E50: =IF(E2=1,-(Overview!K20-Overview!K6),0) -> 0 | F50: =IF(F2=1,-(Overview!L20-Overview!L6),0) -> 0 | G50: =IF(G2=1,-(Overview!M20-Overview!M6),0) -> 0 | H50: =IF(H2=1,-(Overview!N20-Overview!N6),0) -> 0 | I50: =IF(I2=1,-(Overview!O20-Overview!O6),0) -> 0 | J50: =IF(J2=1,-(Overview!P20-Overview!P6),0) -> 0 | ... BJ50: =IF(BJ2=1,-(Overview!BP20-Overview!BP6),0) -> 0
B51: Levered Net CF (for IRR) | C51: =C50+C38+C40+C47 -> -1016753.5 | D51: =D50+D38+D40+D47 -> -28761.022 | E51: =E50+E38+E40+E47 -> -28768.556 | F51: =F50+F38+F40+F47 -> -28776.103 | G51: =G50+G38+G40+G47 -> -28783.661 | H51: =H50+H38+H40+H47 -> -89297.343 | I51: =I50+I38+I40+I47 -> -110851.42 | J51: =J50+J38+J40+J47 -> 5635.5792 | ... BJ51: =BJ50+BJ38+BJ40+BJ47 -> 1064003.1
...

Sheet Overview
A1: RETAIL ACQUISITION MODEL v1 - Keegan Tingey
B2: last updated: 4/5/26
B3: PROPERTY INFO | D3: NOTES | E3: CAPITAL & LEASING ASSUMPTIONS | H3: SOURCES & USES | K3: RETURN METRICS
B4: Property Name | C4: Marconi & Walnut | E4: TI $/SF (New Leases) | F4: 25 | K4: Levered IRR | L4: =IFERROR('Monthly CF'!C55,"--") -> 0.09347612
B5: Property Address | C5: 4949 Marconi Ave, Carmichael CA | E5: TI $/SF (Renewals) | F5: 5 | H5: SOURCES | I5: Amount ($) | K5: Unlevered IRR | L5: =IFERROR('Monthly CF'!C56,"--") -> 0.10299947
B6: Close Date (Model Start) | C6: 46143 | E6: LC % of Total Rent (New) | F6: 0.06 | H6: Loan 1 Proceeds | I6: =F13 -> 1400000 | K6: Equity Multiple | L6: =IFERROR('Monthly CF'!C57,"--") -> 1.4402914
B7: Total NRA (SF) | C7: 17880 | E7: LC % of Total Rent (Renewal) | F7: 0.03 | H7: LP Equity | I7: =I20-I6-I8-I9 -> 988000 | K7: Cash-on-Cash (Yr 2) | L7: =IFERROR('Monthly CF'!C58,"--") -> 0.037251037
B8: Lot Size (acres) | C8: 1.57 | E8: Downtime Between Tenants (mo) | F8: 6 | H8: GP Equity (Co-Invest) | I8: 0 | K8: Going-In Cap Rate | L8: =C17 -> 0.059888996
B9: Year Built | C9: 1984 | E9: Default Renewal Probability | F9: 0.75 | H9: Other Sources | I9: 0 | K9: Exit Cap Rate | L9: =C18 -> 0.08
B10: Parking Spaces | C10: 65 | H10: Total Sources | I10: =SUM(I6:I9) -> 2388000 | K10: Total Equity | L10: =I20-I6 -> 988000
B11: Number of Buildings | C11: 2 | E11: DEBT — LOAN 1 (ACQUISITION) | K11: Total Cash Flow | L11: =IFERROR('Monthly CF'!C59,"--") -> 435007.9
E12: LTV (%) | F12: 0.7 | H12: USES | I12: Amount ($)
B13: KEY ASSUMPTIONS | E13: Loan Amount | F13: =F12*C14 -> 1400000 | H13: Purchase Price | I13: =C14 -> 2000000
B14: Acquisition Price | C14: 2000000 | E14: Int Rate | F14: 0.1 | H14: Closing Costs | I14: =C14*C15 -> 20000
B15: Closing Costs (% of Price) | C15: 0.01 | E15: IO Period | F15: 12 | G15: mos | H15: Loan Origination Fees | I15: =F13*F18 -> 28000
B16: Total Basis | C16: =C14+C14*C15+I18+I19+F13*F18 -> 2298000 | E16: Amo Period | F16: 25 | G16: mos | H16: Acquisition Fee | I16: =C14*F32 -> 40000
B17: Going-In Cap Rate | C17: =IFERROR('Monthly CF'!C22*12/C14,"--") -> 0.059888996 | E17: Loan Term | F17: 60 | G17: mos | H17: Working Capital Reserve | I17: 50000 | J17: need logic on these 3
B18: Exit Cap Rate | C18: 0.08 | D18: also drives refi amnt | E18: Origination Fee (%) | F18: 0.02 | H18: Upfront CapEx Reserve | I18: =SUM('CapEx & TI-LC'!H13:S13) -> 150000
B19: Exit Month | C19: 60 | H19: Upfront TI/LC Reserve | I19: 100000
B20: Selling Costs at Exit (%) | C20: 0.02 | E20: DEBT — LOAN 2 (REFINANCE) | H20: Total Uses | I20: =SUM(I13:I19) -> 2388000
B21: Credit Loss (% of EGI) | C21: 0.05 | E21: Refinance Toggle | F21: ON | H21: Sources - Uses | I21: =I10-I20 -> 0
B22: Replacement Reserve ($/SF/yr) | C22: 0.5 | E22: Refi Month | F22: =IO1_Months -> 12 | H22: Balance Check | I22: =IF(ROUND(I21,0)=0,"✓ BALANCED","✗ ERROR") -> ✓ BALANCED
B23: Annual Rent Growth Rate | C23: 0.03 | E23: Refi LTV (% of Stabilized Value) | F23: 0.7
B24: Property Tax Millage Rate | C24: 0.011742 | E24: Refi Loan Amount | F24: =IFERROR(F23*INDEX('Monthly CF'!C22:BJ22,MATCH(Refi_Month,'Monthly CF'!C2:BJ2,0))* 12/C18,"--") -> 2033910.8
B25: OpEx Annual Growth | C25: 0.02 | D25: driving monthly opex rn | E25: Int Rate | F25: 0.0725
B26: Assessed Value for Taxes | C26: 2000000 | E26: IO Period | F26: 0 | G26: mos
B27: Property Management Fee (% of EGI) | C27: 0.04 | E27: Amo Period | F27: 25 | G27: mos
B28: Additional Income ($/month) | C28: =16513 / 12 -> 1376.0833 | D28: check om: reimb and fireworks | E28: Loan Term | F28: 60 | G28: mos
E29: Origination Fee (%) | F29: 0.02
E31: ENTITY-LEVEL EXPENSES
E32: Acquisition Fee (% of Price) | F32: 0.02
E33: Asset Mgmt Fee (% of Equity) | F33: 0.01
E34: Legal/Acct/Banking ($/month) | F34: 500

Sheet CapEx & TI-LC
A1: CAPITAL EXPENDITURES & TI / LEASING COMMISSIONS
A3: CAPITAL EXPENDITURES
A4: # | B4: Description | C4: Category | D4: Vendor/Notes | E4: Total Cost ($) | F4: Start Month | G4: Spread (mo) | H4: 1 | I4: 2 | J4: 3 | K4: 4 | L4: 5 | M4: 6 | N4: 7 | O4: 8 | P4: 9 | Q4: 10 | R4: 11 | S4: 12 | T4: 13 | U4: 14 | V4: 15 | W4: 16 | X4: 17 | Y4: 18 | Z4: 19 | AA4: 20 | AB4: 21 | AC4: 22 | AD4: 23 | AE4: 24 | AF4: 25 | AG4: 26 | AH4: 27 | AI4: 28 | AJ4: 29 | AK4: 30 | AL4: 31 | AM4: 32 | AN4: 33 | AO4: 34 | AP4: 35 | AQ4: 36 | AR4: 37 | AS4: 38 | AT4: 39 | AU4: 40 | AV4: 41 | AW4: 42 | AX4: 43 | AY4: 44 | AZ4: 45 | BA4: 46 | BB4: 47 | BC4: 48 | BD4: 49 | BE4: 50 | BF4: 51 | BG4: 52 | BH4: 53 | BI4: 54 | BJ4: 55 | BK4: 56 | BL4: 57 | BM4: 58 | BN4: 59 | BO4: 60
A5: 1 | B5: Misc Repairs | C5: Misc | E5: 150000 | F5: 1 | G5: 6 | H5: =IF(AND(1>=$F$5,1<$F$5+$G$5),$E$5/$G$5,0) -> 25000 | I5: =IF(AND(2>=$F$5,2<$F$5+$G$5),$E$5/$G$5,0) -> 25000 | J5: =IF(AND(3>=$F$5,3<$F$5+$G$5),$E$5/$G$5,0) -> 25000 | K5: =IF(AND(4>=$F$5,4<$F$5+$G$5),$E$5/$G$5,0) -> 25000 | L5: =IF(AND(5>=$F$5,5<$F$5+$G$5),$E$5/$G$5,0) -> 25000 | M5: =IF(AND(6>=$F$5,6<$F$5+$G$5),$E$5/$G$5,0) -> 25000 | N5: =IF(AND(7>=$F$5,7<$F$5+$G$5),$E$5/$G$5,0) -> 0 | O5: =IF(AND(8>=$F$5,8<$F$5+$G$5),$E$5/$G$5,0) -> 0 | P5: =IF(AND(9>=$F$5,9<$F$5+$G$5),$E$5/$G$5,0) -> 0 | Q5: =IF(AND(10>=$F$5,10<$F$5+$G$5),$E$5/$G$5,0) -> 0 | R5: =IF(AND(11>=$F$5,11<$F$5+$G$5),$E$5/$G$5,0) -> 0 | S5: =IF(AND(12>=$F$5,12<$F$5+$G$5),$E$5/$G$5,0) -> 0 | T5: =IF(AND(13>=$F$5,13<$F$5+$G$5),$E$5/$G$5,0) -> 0 | U5: =IF(AND(14>=$F$5,14<$F$5+$G$5),$E$5/$G$5,0) -> 0 | V5: =IF(AND(15>=$F$5,15<$F$5+$G$5),$E$5/$G$5,0) -> 0 | W5: =IF(AND(16>=$F$5,16<$F$5+$G$5),$E$5/$G$5,0) -> 0 | X5: =IF(AND(17>=$F$5,17<$F$5+$G$5),$E$5/$G$5,0) -> 0 | Y5: =IF(AND(18>=$F$5,18<$F$5+$G$5),$E$5/$G$5,0) -> 0 | Z5: =IF(AND(19>=$F$5,19<$F$5+$G$5),$E$5/$G$5,0) -> 0 | AA5: =IF(AND(20>=$F$5,20<$F$5+$G$5),$E$5/$G$5,0) -> 0 | AB5: =IF(AND(21>=$F$5,21<$F$5+$G$5),$E$5/$G$5,0) -> 0 | AC5: =IF(AND(22>=$F$5,22<$F$5+$G$5),$E$5/$G$5,0) -> 0 | AD5: =IF(AND(23>=$F$5,23<$F$5+$G$5),$E$5/$G$5,0) -> 0 | AE5: =IF(AND(24>=$F$5,24<$F$5+$G$5),$E$5/$G$5,0) -> 0 | AF5: =IF(AND(25>=$F$5,25<$F$5+$G$5),$E$5/$G$5,0) -> 0 | AG5: =IF(AND(26>=$F$5,26<$F$5+$G$5),$E$5/$G$5,0) -> 0 | AH5: =IF(AND(27>=$F$5,27<$F$5+$G$5),$E$5/$G$5,0) -> 0 | AI5: =IF(AND(28>=$F$5,28<$F$5+$G$5),$E$5/$G$5,0) -> 0 | AJ5: =IF(AND(29>=$F$5,29<$F$5+$G$5),$E$5/$G$5,0) -> 0 | AK5: =IF(AND(30>=$F$5,30<$F$5+$G$5),$E$5/$G$5,0) -> 0 | AL5: =IF(AND(31>=$F$5,31<$F$5+$G$5),$E$5/$G$5,0) -> 0 | AM5: =IF(AND(32>=$F$5,32<$F$5+$G$5),$E$5/$G$5,0) -> 0 | AN5: =IF(AND(33>=$F$5,33<$F$5+$G$5),$E$5/$G$5,0) -> 0 | AO5: =IF(AND(34>=$F$5,34<$F$5+$G$5),$E$5/$G$5,0) -> 0 | AP5: =IF(AND(35>=$F$5,35<$F$5+$G$5),$E$5/$G$5,0) -> 0 | AQ5: =IF(AND(36>=$F$5,36<$F$5+$G$5),$E$5/$G$5,0) -> 0 | AR5: =IF(AND(37>=$F$5,37<$F$5+$G$5),$E$5/$G$5,0) -> 0 | AS5: =IF(AND(38>=$F$5,38<$F$5+$G$5),$E$5/$G$5,0) -> 0 | AT5: =IF(AND(39>=$F$5,39<$F$5+$G$5),$E$5/$G$5,0) -> 0 | AU5: =IF(AND(40>=$F$5,40<$F$5+$G$5),$E$5/$G$5,0) -> 0 | AV5: =IF(AND(41>=$F$5,41<$F$5+$G$5),$E$5/$G$5,0) -> 0 | AW5: =IF(AND(42>=$F$5,42<$F$5+$G$5),$E$5/$G$5,0) -> 0 | AX5: =IF(AND(43>=$F$5,43<$F$5+$G$5),$E$5/$G$5,0) -> 0 | AY5: =IF(AND(44>=$F$5,44<$F$5+$G$5),$E$5/$G$5,0) -> 0 | AZ5: =IF(AND(45>=$F$5,45<$F$5+$G$5),$E$5/$G$5,0) -> 0 | BA5: =IF(AND(46>=$F$5,46<$F$5+$G$5),$E$5/$G$5,0) -> 0 | BB5: =IF(AND(47>=$F$5,47<$F$5+$G$5),$E$5/$G$5,0) -> 0 | BC5: =IF(AND(48>=$F$5,48<$F$5+$G$5),$E$5/$G$5,0) -> 0 | BD5: =IF(AND(49>=$F$5,49<$F$5+$G$5),$E$5/$G$5,0) -> 0 | BE5: =IF(AND(50>=$F$5,50<$F$5+$G$5),$E$5/$G$5,0) -> 0 | BF5: =IF(AND(51>=$F$5,51<$F$5+$G$5),$E$5/$G$5,0) -> 0 | BG5: =IF(AND(52>=$F$5,52<$F$5+$G$5),$E$5/$G$5,0) -> 0 | BH5: =IF(AND(53>=$F$5,53<$F$5+$G$5),$E$5/$G$5,0) -> 0 | BI5: =IF(AND(54>=$F$5,54<$F$5+$G$5),$E$5/$G$5,0) -> 0 | BJ5: =IF(AND(55>=$F$5,55<$F$5+$G$5),$E$5/$G$5,0) -> 0 | BK5: =IF(AND(56>=$F$5,56<$F$5+$G$5),$E$5/$G$5,0) -> 0 | BL5: =IF(AND(57>=$F$5,57<$F$5+$G$5),$E$5/$G$5,0) -> 0 | BM5: =IF(AND(58>=$F$5,58<$F$5+$G$5),$E$5/$G$5,0) -> 0 | BN5: =IF(AND(59>=$F$5,59<$F$5+$G$5),$E$5/$G$5,0) -> 0 | BO5: =IF(AND(60>=$F$5,60<$F$5+$G$5),$E$5/$G$5,0) -> 0
A6: 2 | B6: Asphalt Resurfacing | C6: Site | E6: 0 | F6: 4 | G6: 2 | H6: =IF(AND(1>=$F$6,1<$F$6+$G$6),$E$6/$G$6,0) -> 0 | I6: =IF(AND(2>=$F$6,2<$F$6+$G$6),$E$6/$G$6,0) -> 0 | J6: =IF(AND(3>=$F$6,3<$F$6+$G$6),$E$6/$G$6,0) -> 0 | K6: =IF(AND(4>=$F$6,4<$F$6+$G$6),$E$6/$G$6,0) -> 0 | L6: =IF(AND(5>=$F$6,5<$F$6+$G$6),$E$6/$G$6,0) -> 0 | M6: =IF(AND(6>=$F$6,6<$F$6+$G$6),$E$6/$G$6,0) -> 0 | N6: =IF(AND(7>=$F$6,7<$F$6+$G$6),$E$6/$G$6,0) -> 0 | O6: =IF(AND(8>=$F$6,8<$F$6+$G$6),$E$6/$G$6,0) -> 0 | P6: =IF(AND(9>=$F$6,9<$F$6+$G$6),$E$6/$G$6,0) -> 0 | Q6: =IF(AND(10>=$F$6,10<$F$6+$G$6),$E$6/$G$6,0) -> 0 | R6: =IF(AND(11>=$F$6,11<$F$6+$G$6),$E$6/$G$6,0) -> 0 | S6: =IF(AND(12>=$F$6,12<$F$6+$G$6),$E$6/$G$6,0) -> 0 | T6: =IF(AND(13>=$F$6,13<$F$6+$G$6),$E$6/$G$6,0) -> 0 | U6: =IF(AND(14>=$F$6,14<$F$6+$G$6),$E$6/$G$6,0) -> 0 | V6: =IF(AND(15>=$F$6,15<$F$6+$G$6),$E$6/$G$6,0) -> 0 | W6: =IF(AND(16>=$F$6,16<$F$6+$G$6),$E$6/$G$6,0) -> 0 | X6: =IF(AND(17>=$F$6,17<$F$6+$G$6),$E$6/$G$6,0) -> 0 | Y6: =IF(AND(18>=$F$6,18<$F$6+$G$6),$E$6/$G$6,0) -> 0 | Z6: =IF(AND(19>=$F$6,19<$F$6+$G$6),$E$6/$G$6,0) -> 0 | AA6: =IF(AND(20>=$F$6,20<$F$6+$G$6),$E$6/$G$6,0) -> 0 | AB6: =IF(AND(21>=$F$6,21<$F$6+$G$6),$E$6/$G$6,0) -> 0 | AC6: =IF(AND(22>=$F$6,22<$F$6+$G$6),$E$6/$G$6,0) -> 0 | AD6: =IF(AND(23>=$F$6,23<$F$6+$G$6),$E$6/$G$6,0) -> 0 | AE6: =IF(AND(24>=$F$6,24<$F$6+$G$6),$E$6/$G$6,0) -> 0 | AF6: =IF(AND(25>=$F$6,25<$F$6+$G$6),$E$6/$G$6,0) -> 0 | AG6: =IF(AND(26>=$F$6,26<$F$6+$G$6),$E$6/$G$6,0) -> 0 | AH6: =IF(AND(27>=$F$6,27<$F$6+$G$6),$E$6/$G$6,0) -> 0 | AI6: =IF(AND(28>=$F$6,28<$F$6+$G$6),$E$6/$G$6,0) -> 0 | AJ6: =IF(AND(29>=$F$6,29<$F$6+$G$6),$E$6/$G$6,0) -> 0 | AK6: =IF(AND(30>=$F$6,30<$F$6+$G$6),$E$6/$G$6,0) -> 0 | AL6: =IF(AND(31>=$F$6,31<$F$6+$G$6),$E$6/$G$6,0) -> 0 | AM6: =IF(AND(32>=$F$6,32<$F$6+$G$6),$E$6/$G$6,0) -> 0 | AN6: =IF(AND(33>=$F$6,33<$F$6+$G$6),$E$6/$G$6,0) -> 0 | AO6: =IF(AND(34>=$F$6,34<$F$6+$G$6),$E$6/$G$6,0) -> 0 | AP6: =IF(AND(35>=$F$6,35<$F$6+$G$6),$E$6/$G$6,0) -> 0 | AQ6: =IF(AND(36>=$F$6,36<$F$6+$G$6),$E$6/$G$6,0) -> 0 | AR6: =IF(AND(37>=$F$6,37<$F$6+$G$6),$E$6/$G$6,0) -> 0 | AS6: =IF(AND(38>=$F$6,38<$F$6+$G$6),$E$6/$G$6,0) -> 0 | AT6: =IF(AND(39>=$F$6,39<$F$6+$G$6),$E$6/$G$6,0) -> 0 | AU6: =IF(AND(40>=$F$6,40<$F$6+$G$6),$E$6/$G$6,0) -> 0 | AV6: =IF(AND(41>=$F$6,41<$F$6+$G$6),$E$6/$G$6,0) -> 0 | AW6: =IF(AND(42>=$F$6,42<$F$6+$G$6),$E$6/$G$6,0) -> 0 | AX6: =IF(AND(43>=$F$6,43<$F$6+$G$6),$E$6/$G$6,0) -> 0 | AY6: =IF(AND(44>=$F$6,44<$F$6+$G$6),$E$6/$G$6,0) -> 0 | AZ6: =IF(AND(45>=$F$6,45<$F$6+$G$6),$E$6/$G$6,0) -> 0 | BA6: =IF(AND(46>=$F$6,46<$F$6+$G$6),$E$6/$G$6,0) -> 0 | BB6: =IF(AND(47>=$F$6,47<$F$6+$G$6),$E$6/$G$6,0) -> 0 | BC6: =IF(AND(48>=$F$6,48<$F$6+$G$6),$E$6/$G$6,0) -> 0 | BD6: =IF(AND(49>=$F$6,49<$F$6+$G$6),$E$6/$G$6,0) -> 0 | BE6: =IF(AND(50>=$F$6,50<$F$6+$G$6),$E$6/$G$6,0) -> 0 | BF6: =IF(AND(51>=$F$6,51<$F$6+$G$6),$E$6/$G$6,0) -> 0 | BG6: =IF(AND(52>=$F$6,52<$F$6+$G$6),$E$6/$G$6,0) -> 0 | BH6: =IF(AND(53>=$F$6,53<$F$6+$G$6),$E$6/$G$6,0) -> 0 | BI6: =IF(AND(54>=$F$6,54<$F$6+$G$6),$E$6/$G$6,0) -> 0 | BJ6: =IF(AND(55>=$F$6,55<$F$6+$G$6),$E$6/$G$6,0) -> 0 | BK6: =IF(AND(56>=$F$6,56<$F$6+$G$6),$E$6/$G$6,0) -> 0 | BL6: =IF(AND(57>=$F$6,57<$F$6+$G$6),$E$6/$G$6,0) -> 0 | BM6: =IF(AND(58>=$F$6,58<$F$6+$G$6),$E$6/$G$6,0) -> 0 | BN6: =IF(AND(59>=$F$6,59<$F$6+$G$6),$E$6/$G$6,0) -> 0 | BO6: =IF(AND(60>=$F$6,60<$F$6+$G$6),$E$6/$G$6,0) -> 0
A7: 3 | B7: Dry Rot Repairs | C7: Structural | E7: 0 | F7: 3 | G7: 1 | H7: =IF(AND(1>=$F$7,1<$F$7+$G$7),$E$7/$G$7,0) -> 0 | I7: =IF(AND(2>=$F$7,2<$F$7+$G$7),$E$7/$G$7,0) -> 0 | J7: =IF(AND(3>=$F$7,3<$F$7+$G$7),$E$7/$G$7,0) -> 0 | K7: =IF(AND(4>=$F$7,4<$F$7+$G$7),$E$7/$G$7,0) -> 0 | L7: =IF(AND(5>=$F$7,5<$F$7+$G$7),$E$7/$G$7,0) -> 0 | M7: =IF(AND(6>=$F$7,6<$F$7+$G$7),$E$7/$G$7,0) -> 0 | N7: =IF(AND(7>=$F$7,7<$F$7+$G$7),$E$7/$G$7,0) -> 0 | O7: =IF(AND(8>=$F$7,8<$F$7+$G$7),$E$7/$G$7,0) -> 0 | P7: =IF(AND(9>=$F$7,9<$F$7+$G$7),$E$7/$G$7,0) -> 0 | Q7: =IF(AND(10>=$F$7,10<$F$7+$G$7),$E$7/$G$7,0) -> 0 | R7: =IF(AND(11>=$F$7,11<$F$7+$G$7),$E$7/$G$7,0) -> 0 | S7: =IF(AND(12>=$F$7,12<$F$7+$G$7),$E$7/$G$7,0) -> 0 | T7: =IF(AND(13>=$F$7,13<$F$7+$G$7),$E$7/$G$7,0) -> 0 | U7: =IF(AND(14>=$F$7,14<$F$7+$G$7),$E$7/$G$7,0) -> 0 | V7: =IF(AND(15>=$F$7,15<$F$7+$G$7),$E$7/$G$7,0) -> 0 | W7: =IF(AND(16>=$F$7,16<$F$7+$G$7),$E$7/$G$7,0) -> 0 | X7: =IF(AND(17>=$F$7,17<$F$7+$G$7),$E$7/$G$7,0) -> 0 | Y7: =IF(AND(18>=$F$7,18<$F$7+$G$7),$E$7/$G$7,0) -> 0 | Z7: =IF(AND(19>=$F$7,19<$F$7+$G$7),$E$7/$G$7,0) -> 0 | AA7: =IF(AND(20>=$F$7,20<$F$7+$G$7),$E$7/$G$7,0) -> 0 | AB7: =IF(AND(21>=$F$7,21<$F$7+$G$7),$E$7/$G$7,0) -> 0 | AC7: =IF(AND(22>=$F$7,22<$F$7+$G$7),$E$7/$G$7,0) -> 0 | AD7: =IF(AND(23>=$F$7,23<$F$7+$G$7),$E$7/$G$7,0) -> 0 | AE7: =IF(AND(24>=$F$7,24<$F$7+$G$7),$E$7/$G$7,0) -> 0 | AF7: =IF(AND(25>=$F$7,25<$F$7+$G$7),$E$7/$G$7,0) -> 0 | AG7: =IF(AND(26>=$F$7,26<$F$7+$G$7),$E$7/$G$7,0) -> 0 | AH7: =IF(AND(27>=$F$7,27<$F$7+$G$7),$E$7/$G$7,0) -> 0 | AI7: =IF(AND(28>=$F$7,28<$F$7+$G$7),$E$7/$G$7,0) -> 0 | AJ7: =IF(AND(29>=$F$7,29<$F$7+$G$7),$E$7/$G$7,0) -> 0 | AK7: =IF(AND(30>=$F$7,30<$F$7+$G$7),$E$7/$G$7,0) -> 0 | AL7: =IF(AND(31>=$F$7,31<$F$7+$G$7),$E$7/$G$7,0) -> 0 | AM7: =IF(AND(32>=$F$7,32<$F$7+$G$7),$E$7/$G$7,0) -> 0 | AN7: =IF(AND(33>=$F$7,33<$F$7+$G$7),$E$7/$G$7,0) -> 0 | AO7: =IF(AND(34>=$F$7,34<$F$7+$G$7),$E$7/$G$7,0) -> 0 | AP7: =IF(AND(35>=$F$7,35<$F$7+$G$7),$E$7/$G$7,0) -> 0 | AQ7: =IF(AND(36>=$F$7,36<$F$7+$G$7),$E$7/$G$7,0) -> 0 | AR7: =IF(AND(37>=$F$7,37<$F$7+$G$7),$E$7/$G$7,0) -> 0 | AS7: =IF(AND(38>=$F$7,38<$F$7+$G$7),$E$7/$G$7,0) -> 0 | AT7: =IF(AND(39>=$F$7,39<$F$7+$G$7),$E$7/$G$7,0) -> 0 | AU7: =IF(AND(40>=$F$7,40<$F$7+$G$7),$E$7/$G$7,0) -> 0 | AV7: =IF(AND(41>=$F$7,41<$F$7+$G$7),$E$7/$G$7,0) -> 0 | AW7: =IF(AND(42>=$F$7,42<$F$7+$G$7),$E$7/$G$7,0) -> 0 | AX7: =IF(AND(43>=$F$7,43<$F$7+$G$7),$E$7/$G$7,0) -> 0 | AY7: =IF(AND(44>=$F$7,44<$F$7+$G$7),$E$7/$G$7,0) -> 0 | AZ7: =IF(AND(45>=$F$7,45<$F$7+$G$7),$E$7/$G$7,0) -> 0 | BA7: =IF(AND(46>=$F$7,46<$F$7+$G$7),$E$7/$G$7,0) -> 0 | BB7: =IF(AND(47>=$F$7,47<$F$7+$G$7),$E$7/$G$7,0) -> 0 | BC7: =IF(AND(48>=$F$7,48<$F$7+$G$7),$E$7/$G$7,0) -> 0 | BD7: =IF(AND(49>=$F$7,49<$F$7+$G$7),$E$7/$G$7,0) -> 0 | BE7: =IF(AND(50>=$F$7,50<$F$7+$G$7),$E$7/$G$7,0) -> 0 | BF7: =IF(AND(51>=$F$7,51<$F$7+$G$7),$E$7/$G$7,0) -> 0 | BG7: =IF(AND(52>=$F$7,52<$F$7+$G$7),$E$7/$G$7,0) -> 0 | BH7: =IF(AND(53>=$F$7,53<$F$7+$G$7),$E$7/$G$7,0) -> 0 | BI7: =IF(AND(54>=$F$7,54<$F$7+$G$7),$E$7/$G$7,0) -> 0 | BJ7: =IF(AND(55>=$F$7,55<$F$7+$G$7),$E$7/$G$7,0) -> 0 | BK7: =IF(AND(56>=$F$7,56<$F$7+$G$7),$E$7/$G$7,0) -> 0 | BL7: =IF(AND(57>=$F$7,57<$F$7+$G$7),$E$7/$G$7,0) -> 0 | BM7: =IF(AND(58>=$F$7,58<$F$7+$G$7),$E$7/$G$7,0) -> 0 | BN7: =IF(AND(59>=$F$7,59<$F$7+$G$7),$E$7/$G$7,0) -> 0 | BO7: =IF(AND(60>=$F$7,60<$F$7+$G$7),$E$7/$G$7,0) -> 0
A8: 4 | B8: Gutter Repairs | C8: Structural | E8: 0 | F8: 6 | G8: 1 | H8: =IF(AND(1>=$F$8,1<$F$8+$G$8),$E$8/$G$8,0) -> 0 | I8: =IF(AND(2>=$F$8,2<$F$8+$G$8),$E$8/$G$8,0) -> 0 | J8: =IF(AND(3>=$F$8,3<$F$8+$G$8),$E$8/$G$8,0) -> 0 | K8: =IF(AND(4>=$F$8,4<$F$8+$G$8),$E$8/$G$8,0) -> 0 | L8: =IF(AND(5>=$F$8,5<$F$8+$G$8),$E$8/$G$8,0) -> 0 | M8: =IF(AND(6>=$F$8,6<$F$8+$G$8),$E$8/$G$8,0) -> 0 | N8: =IF(AND(7>=$F$8,7<$F$8+$G$8),$E$8/$G$8,0) -> 0 | O8: =IF(AND(8>=$F$8,8<$F$8+$G$8),$E$8/$G$8,0) -> 0 | P8: =IF(AND(9>=$F$8,9<$F$8+$G$8),$E$8/$G$8,0) -> 0 | Q8: =IF(AND(10>=$F$8,10<$F$8+$G$8),$E$8/$G$8,0) -> 0 | R8: =IF(AND(11>=$F$8,11<$F$8+$G$8),$E$8/$G$8,0) -> 0 | S8: =IF(AND(12>=$F$8,12<$F$8+$G$8),$E$8/$G$8,0) -> 0 | T8: =IF(AND(13>=$F$8,13<$F$8+$G$8),$E$8/$G$8,0) -> 0 | U8: =IF(AND(14>=$F$8,14<$F$8+$G$8),$E$8/$G$8,0) -> 0 | V8: =IF(AND(15>=$F$8,15<$F$8+$G$8),$E$8/$G$8,0) -> 0 | W8: =IF(AND(16>=$F$8,16<$F$8+$G$8),$E$8/$G$8,0) -> 0 | X8: =IF(AND(17>=$F$8,17<$F$8+$G$8),$E$8/$G$8,0) -> 0 | Y8: =IF(AND(18>=$F$8,18<$F$8+$G$8),$E$8/$G$8,0) -> 0 | Z8: =IF(AND(19>=$F$8,19<$F$8+$G$8),$E$8/$G$8,0) -> 0 | AA8: =IF(AND(20>=$F$8,20<$F$8+$G$8),$E$8/$G$8,0) -> 0 | AB8: =IF(AND(21>=$F$8,21<$F$8+$G$8),$E$8/$G$8,0) -> 0 | AC8: =IF(AND(22>=$F$8,22<$F$8+$G$8),$E$8/$G$8,0) -> 0 | AD8: =IF(AND(23>=$F$8,23<$F$8+$G$8),$E$8/$G$8,0) -> 0 | AE8: =IF(AND(24>=$F$8,24<$F$8+$G$8),$E$8/$G$8,0) -> 0 | AF8: =IF(AND(25>=$F$8,25<$F$8+$G$8),$E$8/$G$8,0) -> 0 | AG8: =IF(AND(26>=$F$8,26<$F$8+$G$8),$E$8/$G$8,0) -> 0 | AH8: =IF(AND(27>=$F$8,27<$F$8+$G$8),$E$8/$G$8,0) -> 0 | AI8: =IF(AND(28>=$F$8,28<$F$8+$G$8),$E$8/$G$8,0) -> 0 | AJ8: =IF(AND(29>=$F$8,29<$F$8+$G$8),$E$8/$G$8,0) -> 0 | AK8: =IF(AND(30>=$F$8,30<$F$8+$G$8),$E$8/$G$8,0) -> 0 | AL8: =IF(AND(31>=$F$8,31<$F$8+$G$8),$E$8/$G$8,0) -> 0 | AM8: =IF(AND(32>=$F$8,32<$F$8+$G$8),$E$8/$G$8,0) -> 0 | AN8: =IF(AND(33>=$F$8,33<$F$8+$G$8),$E$8/$G$8,0) -> 0 | AO8: =IF(AND(34>=$F$8,34<$F$8+$G$8),$E$8/$G$8,0) -> 0 | AP8: =IF(AND(35>=$F$8,35<$F$8+$G$8),$E$8/$G$8,0) -> 0 | AQ8: =IF(AND(36>=$F$8,36<$F$8+$G$8),$E$8/$G$8,0) -> 0 | AR8: =IF(AND(37>=$F$8,37<$F$8+$G$8),$E$8/$G$8,0) -> 0 | AS8: =IF(AND(38>=$F$8,38<$F$8+$G$8),$E$8/$G$8,0) -> 0 | AT8: =IF(AND(39>=$F$8,39<$F$8+$G$8),$E$8/$G$8,0) -> 0 | AU8: =IF(AND(40>=$F$8,40<$F$8+$G$8),$E$8/$G$8,0) -> 0 | AV8: =IF(AND(41>=$F$8,41<$F$8+$G$8),$E$8/$G$8,0) -> 0 | AW8: =IF(AND(42>=$F$8,42<$F$8+$G$8),$E$8/$G$8,0) -> 0 | AX8: =IF(AND(43>=$F$8,43<$F$8+$G$8),$E$8/$G$8,0) -> 0 | AY8: =IF(AND(44>=$F$8,44<$F$8+$G$8),$E$8/$G$8,0) -> 0 | AZ8: =IF(AND(45>=$F$8,45<$F$8+$G$8),$E$8/$G$8,0) -> 0 | BA8: =IF(AND(46>=$F$8,46<$F$8+$G$8),$E$8/$G$8,0) -> 0 | BB8: =IF(AND(47>=$F$8,47<$F$8+$G$8),$E$8/$G$8,0) -> 0 | BC8: =IF(AND(48>=$F$8,48<$F$8+$G$8),$E$8/$G$8,0) -> 0 | BD8: =IF(AND(49>=$F$8,49<$F$8+$G$8),$E$8/$G$8,0) -> 0 | BE8: =IF(AND(50>=$F$8,50<$F$8+$G$8),$E$8/$G$8,0) -> 0 | BF8: =IF(AND(51>=$F$8,51<$F$8+$G$8),$E$8/$G$8,0) -> 0 | BG8: =IF(AND(52>=$F$8,52<$F$8+$G$8),$E$8/$G$8,0) -> 0 | BH8: =IF(AND(53>=$F$8,53<$F$8+$G$8),$E$8/$G$8,0) -> 0 | BI8: =IF(AND(54>=$F$8,54<$F$8+$G$8),$E$8/$G$8,0) -> 0 | BJ8: =IF(AND(55>=$F$8,55<$F$8+$G$8),$E$8/$G$8,0) -> 0 | BK8: =IF(AND(56>=$F$8,56<$F$8+$G$8),$E$8/$G$8,0) -> 0 | BL8: =IF(AND(57>=$F$8,57<$F$8+$G$8),$E$8/$G$8,0) -> 0 | BM8: =IF(AND(58>=$F$8,58<$F$8+$G$8),$E$8/$G$8,0) -> 0 | BN8: =IF(AND(59>=$F$8,59<$F$8+$G$8),$E$8/$G$8,0) -> 0 | BO8: =IF(AND(60>=$F$8,60<$F$8+$G$8),$E$8/$G$8,0) -> 0
A9: 5 | B9: Exterior LED Lighting | C9: Electrical | E9: 0 | F9: 5 | G9: 1 | H9: =IF(AND(1>=$F$9,1<$F$9+$G$9),$E$9/$G$9,0) -> 0 | I9: =IF(AND(2>=$F$9,2<$F$9+$G$9),$E$9/$G$9,0) -> 0 | J9: =IF(AND(3>=$F$9,3<$F$9+$G$9),$E$9/$G$9,0) -> 0 | K9: =IF(AND(4>=$F$9,4<$F$9+$G$9),$E$9/$G$9,0) -> 0 | L9: =IF(AND(5>=$F$9,5<$F$9+$G$9),$E$9/$G$9,0) -> 0 | M9: =IF(AND(6>=$F$9,6<$F$9+$G$9),$E$9/$G$9,0) -> 0 | N9: =IF(AND(7>=$F$9,7<$F$9+$G$9),$E$9/$G$9,0) -> 0 | O9: =IF(AND(8>=$F$9,8<$F$9+$G$9),$E$9/$G$9,0) -> 0 | P9: =IF(AND(9>=$F$9,9<$F$9+$G$9),$E$9/$G$9,0) -> 0 | Q9: =IF(AND(10>=$F$9,10<$F$9+$G$9),$E$9/$G$9,0) -> 0 | R9: =IF(AND(11>=$F$9,11<$F$9+$G$9),$E$9/$G$9,0) -> 0 | S9: =IF(AND(12>=$F$9,12<$F$9+$G$9),$E$9/$G$9,0) -> 0 | T9: =IF(AND(13>=$F$9,13<$F$9+$G$9),$E$9/$G$9,0) -> 0 | U9: =IF(AND(14>=$F$9,14<$F$9+$G$9),$E$9/$G$9,0) -> 0 | V9: =IF(AND(15>=$F$9,15<$F$9+$G$9),$E$9/$G$9,0) -> 0 | W9: =IF(AND(16>=$F$9,16<$F$9+$G$9),$E$9/$G$9,0) -> 0 | X9: =IF(AND(17>=$F$9,17<$F$9+$G$9),$E$9/$G$9,0) -> 0 | Y9: =IF(AND(18>=$F$9,18<$F$9+$G$9),$E$9/$G$9,0) -> 0 | Z9: =IF(AND(19>=$F$9,19<$F$9+$G$9),$E$9/$G$9,0) -> 0 | AA9: =IF(AND(20>=$F$9,20<$F$9+$G$9),$E$9/$G$9,0) -> 0 | AB9: =IF(AND(21>=$F$9,21<$F$9+$G$9),$E$9/$G$9,0) -> 0 | AC9: =IF(AND(22>=$F$9,22<$F$9+$G$9),$E$9/$G$9,0) -> 0 | AD9: =IF(AND(23>=$F$9,23<$F$9+$G$9),$E$9/$G$9,0) -> 0 | AE9: =IF(AND(24>=$F$9,24<$F$9+$G$9),$E$9/$G$9,0) -> 0 | AF9: =IF(AND(25>=$F$9,25<$F$9+$G$9),$E$9/$G$9,0) -> 0 | AG9: =IF(AND(26>=$F$9,26<$F$9+$G$9),$E$9/$G$9,0) -> 0 | AH9: =IF(AND(27>=$F$9,27<$F$9+$G$9),$E$9/$G$9,0) -> 0 | AI9: =IF(AND(28>=$F$9,28<$F$9+$G$9),$E$9/$G$9,0) -> 0 | AJ9: =IF(AND(29>=$F$9,29<$F$9+$G$9),$E$9/$G$9,0) -> 0 | AK9: =IF(AND(30>=$F$9,30<$F$9+$G$9),$E$9/$G$9,0) -> 0 | AL9: =IF(AND(31>=$F$9,31<$F$9+$G$9),$E$9/$G$9,0) -> 0 | AM9: =IF(AND(32>=$F$9,32<$F$9+$G$9),$E$9/$G$9,0) -> 0 | AN9: =IF(AND(33>=$F$9,33<$F$9+$G$9),$E$9/$G$9,0) -> 0 | AO9: =IF(AND(34>=$F$9,34<$F$9+$G$9),$E$9/$G$9,0) -> 0 | AP9: =IF(AND(35>=$F$9,35<$F$9+$G$9),$E$9/$G$9,0) -> 0 | AQ9: =IF(AND(36>=$F$9,36<$F$9+$G$9),$E$9/$G$9,0) -> 0 | AR9: =IF(AND(37>=$F$9,37<$F$9+$G$9),$E$9/$G$9,0) -> 0 | AS9: =IF(AND(38>=$F$9,38<$F$9+$G$9),$E$9/$G$9,0) -> 0 | AT9: =IF(AND(39>=$F$9,39<$F$9+$G$9),$E$9/$G$9,0) -> 0 | AU9: =IF(AND(40>=$F$9,40<$F$9+$G$9),$E$9/$G$9,0) -> 0 | AV9: =IF(AND(41>=$F$9,41<$F$9+$G$9),$E$9/$G$9,0) -> 0 | AW9: =IF(AND(42>=$F$9,42<$F$9+$G$9),$E$9/$G$9,0) -> 0 | AX9: =IF(AND(43>=$F$9,43<$F$9+$G$9),$E$9/$G$9,0) -> 0 | AY9: =IF(AND(44>=$F$9,44<$F$9+$G$9),$E$9/$G$9,0) -> 0 | AZ9: =IF(AND(45>=$F$9,45<$F$9+$G$9),$E$9/$G$9,0) -> 0 | BA9: =IF(AND(46>=$F$9,46<$F$9+$G$9),$E$9/$G$9,0) -> 0 | BB9: =IF(AND(47>=$F$9,47<$F$9+$G$9),$E$9/$G$9,0) -> 0 | BC9: =IF(AND(48>=$F$9,48<$F$9+$G$9),$E$9/$G$9,0) -> 0 | BD9: =IF(AND(49>=$F$9,49<$F$9+$G$9),$E$9/$G$9,0) -> 0 | BE9: =IF(AND(50>=$F$9,50<$F$9+$G$9),$E$9/$G$9,0) -> 0 | BF9: =IF(AND(51>=$F$9,51<$F$9+$G$9),$E$9/$G$9,0) -> 0 | BG9: =IF(AND(52>=$F$9,52<$F$9+$G$9),$E$9/$G$9,0) -> 0 | BH9: =IF(AND(53>=$F$9,53<$F$9+$G$9),$E$9/$G$9,0) -> 0 | BI9: =IF(AND(54>=$F$9,54<$F$9+$G$9),$E$9/$G$9,0) -> 0 | BJ9: =IF(AND(55>=$F$9,55<$F$9+$G$9),$E$9/$G$9,0) -> 0 | BK9: =IF(AND(56>=$F$9,56<$F$9+$G$9),$E$9/$G$9,0) -> 0 | BL9: =IF(AND(57>=$F$9,57<$F$9+$G$9),$E$9/$G$9,0) -> 0 | BM9: =IF(AND(58>=$F$9,58<$F$9+$G$9),$E$9/$G$9,0) -> 0 | BN9: =IF(AND(59>=$F$9,59<$F$9+$G$9),$E$9/$G$9,0) -> 0 | BO9: =IF(AND(60>=$F$9,60<$F$9+$G$9),$E$9/$G$9,0) -> 0
A10: 6 | B10: Sewer Line Repair | C10: Mechanical | E10: 0 | F10: 6 | G10: 1 | H10: =IF(AND(1>=$F$10,1<$F$10+$G$10),$E$10/$G$10,0) -> 0 | I10: =IF(AND(2>=$F$10,2<$F$10+$G$10),$E$10/$G$10,0) -> 0 | J10: =IF(AND(3>=$F$10,3<$F$10+$G$10),$E$10/$G$10,0) -> 0 | K10: =IF(AND(4>=$F$10,4<$F$10+$G$10),$E$10/$G$10,0) -> 0 | L10: =IF(AND(5>=$F$10,5<$F$10+$G$10),$E$10/$G$10,0) -> 0 | M10: =IF(AND(6>=$F$10,6<$F$10+$G$10),$E$10/$G$10,0) -> 0 | N10: =IF(AND(7>=$F$10,7<$F$10+$G$10),$E$10/$G$10,0) -> 0 | O10: =IF(AND(8>=$F$10,8<$F$10+$G$10),$E$10/$G$10,0) -> 0 | P10: =IF(AND(9>=$F$10,9<$F$10+$G$10),$E$10/$G$10,0) -> 0 | Q10: =IF(AND(10>=$F$10,10<$F$10+$G$10),$E$10/$G$10,0) -> 0 | R10: =IF(AND(11>=$F$10,11<$F$10+$G$10),$E$10/$G$10,0) -> 0 | S10: =IF(AND(12>=$F$10,12<$F$10+$G$10),$E$10/$G$10,0) -> 0 | T10: =IF(AND(13>=$F$10,13<$F$10+$G$10),$E$10/$G$10,0) -> 0 | U10: =IF(AND(14>=$F$10,14<$F$10+$G$10),$E$10/$G$10,0) -> 0 | V10: =IF(AND(15>=$F$10,15<$F$10+$G$10),$E$10/$G$10,0) -> 0 | W10: =IF(AND(16>=$F$10,16<$F$10+$G$10),$E$10/$G$10,0) -> 0 | X10: =IF(AND(17>=$F$10,17<$F$10+$G$10),$E$10/$G$10,0) -> 0 | Y10: =IF(AND(18>=$F$10,18<$F$10+$G$10),$E$10/$G$10,0) -> 0 | Z10: =IF(AND(19>=$F$10,19<$F$10+$G$10),$E$10/$G$10,0) -> 0 | AA10: =IF(AND(20>=$F$10,20<$F$10+$G$10),$E$10/$G$10,0) -> 0 | AB10: =IF(AND(21>=$F$10,21<$F$10+$G$10),$E$10/$G$10,0) -> 0 | AC10: =IF(AND(22>=$F$10,22<$F$10+$G$10),$E$10/$G$10,0) -> 0 | AD10: =IF(AND(23>=$F$10,23<$F$10+$G$10),$E$10/$G$10,0) -> 0 | AE10: =IF(AND(24>=$F$10,24<$F$10+$G$10),$E$10/$G$10,0) -> 0 | AF10: =IF(AND(25>=$F$10,25<$F$10+$G$10),$E$10/$G$10,0) -> 0 | AG10: =IF(AND(26>=$F$10,26<$F$10+$G$10),$E$10/$G$10,0) -> 0 | AH10: =IF(AND(27>=$F$10,27<$F$10+$G$10),$E$10/$G$10,0) -> 0 | AI10: =IF(AND(28>=$F$10,28<$F$10+$G$10),$E$10/$G$10,0) -> 0 | AJ10: =IF(AND(29>=$F$10,29<$F$10+$G$10),$E$10/$G$10,0) -> 0 | AK10: =IF(AND(30>=$F$10,30<$F$10+$G$10),$E$10/$G$10,0) -> 0 | AL10: =IF(AND(31>=$F$10,31<$F$10+$G$10),$E$10/$G$10,0) -> 0 | AM10: =IF(AND(32>=$F$10,32<$F$10+$G$10),$E$10/$G$10,0) -> 0 | AN10: =IF(AND(33>=$F$10,33<$F$10+$G$10),$E$10/$G$10,0) -> 0 | AO10: =IF(AND(34>=$F$10,34<$F$10+$G$10),$E$10/$G$10,0) -> 0 | AP10: =IF(AND(35>=$F$10,35<$F$10+$G$10),$E$10/$G$10,0) -> 0 | AQ10: =IF(AND(36>=$F$10,36<$F$10+$G$10),$E$10/$G$10,0) -> 0 | AR10: =IF(AND(37>=$F$10,37<$F$10+$G$10),$E$10/$G$10,0) -> 0 | AS10: =IF(AND(38>=$F$10,38<$F$10+$G$10),$E$10/$G$10,0) -> 0 | AT10: =IF(AND(39>=$F$10,39<$F$10+$G$10),$E$10/$G$10,0) -> 0 | AU10: =IF(AND(40>=$F$10,40<$F$10+$G$10),$E$10/$G$10,0) -> 0 | AV10: =IF(AND(41>=$F$10,41<$F$10+$G$10),$E$10/$G$10,0) -> 0 | AW10: =IF(AND(42>=$F$10,42<$F$10+$G$10),$E$10/$G$10,0) -> 0 | AX10: =IF(AND(43>=$F$10,43<$F$10+$G$10),$E$10/$G$10,0) -> 0 | AY10: =IF(AND(44>=$F$10,44<$F$10+$G$10),$E$10/$G$10,0) -> 0 | AZ10: =IF(AND(45>=$F$10,45<$F$10+$G$10),$E$10/$G$10,0) -> 0 | BA10: =IF(AND(46>=$F$10,46<$F$10+$G$10),$E$10/$G$10,0) -> 0 | BB10: =IF(AND(47>=$F$10,47<$F$10+$G$10),$E$10/$G$10,0) -> 0 | BC10: =IF(AND(48>=$F$10,48<$F$10+$G$10),$E$10/$G$10,0) -> 0 | BD10: =IF(AND(49>=$F$10,49<$F$10+$G$10),$E$10/$G$10,0) -> 0 | BE10: =IF(AND(50>=$F$10,50<$F$10+$G$10),$E$10/$G$10,0) -> 0 | BF10: =IF(AND(51>=$F$10,51<$F$10+$G$10),$E$10/$G$10,0) -> 0 | BG10: =IF(AND(52>=$F$10,52<$F$10+$G$10),$E$10/$G$10,0) -> 0 | BH10: =IF(AND(53>=$F$10,53<$F$10+$G$10),$E$10/$G$10,0) -> 0 | BI10: =IF(AND(54>=$F$10,54<$F$10+$G$10),$E$10/$G$10,0) -> 0 | BJ10: =IF(AND(55>=$F$10,55<$F$10+$G$10),$E$10/$G$10,0) -> 0 | BK10: =IF(AND(56>=$F$10,56<$F$10+$G$10),$E$10/$G$10,0) -> 0 | BL10: =IF(AND(57>=$F$10,57<$F$10+$G$10),$E$10/$G$10,0) -> 0 | BM10: =IF(AND(58>=$F$10,58<$F$10+$G$10),$E$10/$G$10,0) -> 0 | BN10: =IF(AND(59>=$F$10,59<$F$10+$G$10),$E$10/$G$10,0) -> 0 | BO10: =IF(AND(60>=$F$10,60<$F$10+$G$10),$E$10/$G$10,0) -> 0
A11: 7 | B11: Tree Service | C11: Site | E11: 0 | F11: 2 | G11: 1 | H11: =IF(AND(1>=$F$11,1<$F$11+$G$11),$E$11/$G$11,0) -> 0 | I11: =IF(AND(2>=$F$11,2<$F$11+$G$11),$E$11/$G$11,0) -> 0 | J11: =IF(AND(3>=$F$11,3<$F$11+$G$11),$E$11/$G$11,0) -> 0 | K11: =IF(AND(4>=$F$11,4<$F$11+$G$11),$E$11/$G$11,0) -> 0 | L11: =IF(AND(5>=$F$11,5<$F$11+$G$11),$E$11/$G$11,0) -> 0 | M11: =IF(AND(6>=$F$11,6<$F$11+$G$11),$E$11/$G$11,0) -> 0 | N11: =IF(AND(7>=$F$11,7<$F$11+$G$11),$E$11/$G$11,0) -> 0 | O11: =IF(AND(8>=$F$11,8<$F$11+$G$11),$E$11/$G$11,0) -> 0 | P11: =IF(AND(9>=$F$11,9<$F$11+$G$11),$E$11/$G$11,0) -> 0 | Q11: =IF(AND(10>=$F$11,10<$F$11+$G$11),$E$11/$G$11,0) -> 0 | R11: =IF(AND(11>=$F$11,11<$F$11+$G$11),$E$11/$G$11,0) -> 0 | S11: =IF(AND(12>=$F$11,12<$F$11+$G$11),$E$11/$G$11,0) -> 0 | T11: =IF(AND(13>=$F$11,13<$F$11+$G$11),$E$11/$G$11,0) -> 0 | U11: =IF(AND(14>=$F$11,14<$F$11+$G$11),$E$11/$G$11,0) -> 0 | V11: =IF(AND(15>=$F$11,15<$F$11+$G$11),$E$11/$G$11,0) -> 0 | W11: =IF(AND(16>=$F$11,16<$F$11+$G$11),$E$11/$G$11,0) -> 0 | X11: =IF(AND(17>=$F$11,17<$F$11+$G$11),$E$11/$G$11,0) -> 0 | Y11: =IF(AND(18>=$F$11,18<$F$11+$G$11),$E$11/$G$11,0) -> 0 | Z11: =IF(AND(19>=$F$11,19<$F$11+$G$11),$E$11/$G$11,0) -> 0 | AA11: =IF(AND(20>=$F$11,20<$F$11+$G$11),$E$11/$G$11,0) -> 0 | AB11: =IF(AND(21>=$F$11,21<$F$11+$G$11),$E$11/$G$11,0) -> 0 | AC11: =IF(AND(22>=$F$11,22<$F$11+$G$11),$E$11/$G$11,0) -> 0 | AD11: =IF(AND(23>=$F$11,23<$F$11+$G$11),$E$11/$G$11,0) -> 0 | AE11: =IF(AND(24>=$F$11,24<$F$11+$G$11),$E$11/$G$11,0) -> 0 | AF11: =IF(AND(25>=$F$11,25<$F$11+$G$11),$E$11/$G$11,0) -> 0 | AG11: =IF(AND(26>=$F$11,26<$F$11+$G$11),$E$11/$G$11,0) -> 0 | AH11: =IF(AND(27>=$F$11,27<$F$11+$G$11),$E$11/$G$11,0) -> 0 | AI11: =IF(AND(28>=$F$11,28<$F$11+$G$11),$E$11/$G$11,0) -> 0 | AJ11: =IF(AND(29>=$F$11,29<$F$11+$G$11),$E$11/$G$11,0) -> 0 | AK11: =IF(AND(30>=$F$11,30<$F$11+$G$11),$E$11/$G$11,0) -> 0 | AL11: =IF(AND(31>=$F$11,31<$F$11+$G$11),$E$11/$G$11,0) -> 0 | AM11: =IF(AND(32>=$F$11,32<$F$11+$G$11),$E$11/$G$11,0) -> 0 | AN11: =IF(AND(33>=$F$11,33<$F$11+$G$11),$E$11/$G$11,0) -> 0 | AO11: =IF(AND(34>=$F$11,34<$F$11+$G$11),$E$11/$G$11,0) -> 0 | AP11: =IF(AND(35>=$F$11,35<$F$11+$G$11),$E$11/$G$11,0) -> 0 | AQ11: =IF(AND(36>=$F$11,36<$F$11+$G$11),$E$11/$G$11,0) -> 0 | AR11: =IF(AND(37>=$F$11,37<$F$11+$G$11),$E$11/$G$11,0) -> 0 | AS11: =IF(AND(38>=$F$11,38<$F$11+$G$11),$E$11/$G$11,0) -> 0 | AT11: =IF(AND(39>=$F$11,39<$F$11+$G$11),$E$11/$G$11,0) -> 0 | AU11: =IF(AND(40>=$F$11,40<$F$11+$G$11),$E$11/$G$11,0) -> 0 | AV11: =IF(AND(41>=$F$11,41<$F$11+$G$11),$E$11/$G$11,0) -> 0 | AW11: =IF(AND(42>=$F$11,42<$F$11+$G$11),$E$11/$G$11,0) -> 0 | AX11: =IF(AND(43>=$F$11,43<$F$11+$G$11),$E$11/$G$11,0) -> 0 | AY11: =IF(AND(44>=$F$11,44<$F$11+$G$11),$E$11/$G$11,0) -> 0 | AZ11: =IF(AND(45>=$F$11,45<$F$11+$G$11),$E$11/$G$11,0) -> 0 | BA11: =IF(AND(46>=$F$11,46<$F$11+$G$11),$E$11/$G$11,0) -> 0 | BB11: =IF(AND(47>=$F$11,47<$F$11+$G$11),$E$11/$G$11,0) -> 0 | BC11: =IF(AND(48>=$F$11,48<$F$11+$G$11),$E$11/$G$11,0) -> 0 | BD11: =IF(AND(49>=$F$11,49<$F$11+$G$11),$E$11/$G$11,0) -> 0 | BE11: =IF(AND(50>=$F$11,50<$F$11+$G$11),$E$11/$G$11,0) -> 0 | BF11: =IF(AND(51>=$F$11,51<$F$11+$G$11),$E$11/$G$11,0) -> 0 | BG11: =IF(AND(52>=$F$11,52<$F$11+$G$11),$E$11/$G$11,0) -> 0 | BH11: =IF(AND(53>=$F$11,53<$F$11+$G$11),$E$11/$G$11,0) -> 0 | BI11: =IF(AND(54>=$F$11,54<$F$11+$G$11),$E$11/$G$11,0) -> 0 | BJ11: =IF(AND(55>=$F$11,55<$F$11+$G$11),$E$11/$G$11,0) -> 0 | BK11: =IF(AND(56>=$F$11,56<$F$11+$G$11),$E$11/$G$11,0) -> 0 | BL11: =IF(AND(57>=$F$11,57<$F$11+$G$11),$E$11/$G$11,0) -> 0 | BM11: =IF(AND(58>=$F$11,58<$F$11+$G$11),$E$11/$G$11,0) -> 0 | BN11: =IF(AND(59>=$F$11,59<$F$11+$G$11),$E$11/$G$11,0) -> 0 | BO11: =IF(AND(60>=$F$11,60<$F$11+$G$11),$E$11/$G$11,0) -> 0
A12: 8 | B12: Misc Repairs | C12: Cosmetic | E12: 0 | F12: 3 | G12: 1 | H12: =IF(AND(1>=$F$12,1<$F$12+$G$12),$E$12/$G$12,0) -> 0 | I12: =IF(AND(2>=$F$12,2<$F$12+$G$12),$E$12/$G$12,0) -> 0 | J12: =IF(AND(3>=$F$12,3<$F$12+$G$12),$E$12/$G$12,0) -> 0 | K12: =IF(AND(4>=$F$12,4<$F$12+$G$12),$E$12/$G$12,0) -> 0 | L12: =IF(AND(5>=$F$12,5<$F$12+$G$12),$E$12/$G$12,0) -> 0 | M12: =IF(AND(6>=$F$12,6<$F$12+$G$12),$E$12/$G$12,0) -> 0 | N12: =IF(AND(7>=$F$12,7<$F$12+$G$12),$E$12/$G$12,0) -> 0 | O12: =IF(AND(8>=$F$12,8<$F$12+$G$12),$E$12/$G$12,0) -> 0 | P12: =IF(AND(9>=$F$12,9<$F$12+$G$12),$E$12/$G$12,0) -> 0 | Q12: =IF(AND(10>=$F$12,10<$F$12+$G$12),$E$12/$G$12,0) -> 0 | R12: =IF(AND(11>=$F$12,11<$F$12+$G$12),$E$12/$G$12,0) -> 0 | S12: =IF(AND(12>=$F$12,12<$F$12+$G$12),$E$12/$G$12,0) -> 0 | T12: =IF(AND(13>=$F$12,13<$F$12+$G$12),$E$12/$G$12,0) -> 0 | U12: =IF(AND(14>=$F$12,14<$F$12+$G$12),$E$12/$G$12,0) -> 0 | V12: =IF(AND(15>=$F$12,15<$F$12+$G$12),$E$12/$G$12,0) -> 0 | W12: =IF(AND(16>=$F$12,16<$F$12+$G$12),$E$12/$G$12,0) -> 0 | X12: =IF(AND(17>=$F$12,17<$F$12+$G$12),$E$12/$G$12,0) -> 0 | Y12: =IF(AND(18>=$F$12,18<$F$12+$G$12),$E$12/$G$12,0) -> 0 | Z12: =IF(AND(19>=$F$12,19<$F$12+$G$12),$E$12/$G$12,0) -> 0 | AA12: =IF(AND(20>=$F$12,20<$F$12+$G$12),$E$12/$G$12,0) -> 0 | AB12: =IF(AND(21>=$F$12,21<$F$12+$G$12),$E$12/$G$12,0) -> 0 | AC12: =IF(AND(22>=$F$12,22<$F$12+$G$12),$E$12/$G$12,0) -> 0 | AD12: =IF(AND(23>=$F$12,23<$F$12+$G$12),$E$12/$G$12,0) -> 0 | AE12: =IF(AND(24>=$F$12,24<$F$12+$G$12),$E$12/$G$12,0) -> 0 | AF12: =IF(AND(25>=$F$12,25<$F$12+$G$12),$E$12/$G$12,0) -> 0 | AG12: =IF(AND(26>=$F$12,26<$F$12+$G$12),$E$12/$G$12,0) -> 0 | AH12: =IF(AND(27>=$F$12,27<$F$12+$G$12),$E$12/$G$12,0) -> 0 | AI12: =IF(AND(28>=$F$12,28<$F$12+$G$12),$E$12/$G$12,0) -> 0 | AJ12: =IF(AND(29>=$F$12,29<$F$12+$G$12),$E$12/$G$12,0) -> 0 | AK12: =IF(AND(30>=$F$12,30<$F$12+$G$12),$E$12/$G$12,0) -> 0 | AL12: =IF(AND(31>=$F$12,31<$F$12+$G$12),$E$12/$G$12,0) -> 0 | AM12: =IF(AND(32>=$F$12,32<$F$12+$G$12),$E$12/$G$12,0) -> 0 | AN12: =IF(AND(33>=$F$12,33<$F$12+$G$12),$E$12/$G$12,0) -> 0 | AO12: =IF(AND(34>=$F$12,34<$F$12+$G$12),$E$12/$G$12,0) -> 0 | AP12: =IF(AND(35>=$F$12,35<$F$12+$G$12),$E$12/$G$12,0) -> 0 | AQ12: =IF(AND(36>=$F$12,36<$F$12+$G$12),$E$12/$G$12,0) -> 0 | AR12: =IF(AND(37>=$F$12,37<$F$12+$G$12),$E$12/$G$12,0) -> 0 | AS12: =IF(AND(38>=$F$12,38<$F$12+$G$12),$E$12/$G$12,0) -> 0 | AT12: =IF(AND(39>=$F$12,39<$F$12+$G$12),$E$12/$G$12,0) -> 0 | AU12: =IF(AND(40>=$F$12,40<$F$12+$G$12),$E$12/$G$12,0) -> 0 | AV12: =IF(AND(41>=$F$12,41<$F$12+$G$12),$E$12/$G$12,0) -> 0 | AW12: =IF(AND(42>=$F$12,42<$F$12+$G$12),$E$12/$G$12,0) -> 0 | AX12: =IF(AND(43>=$F$12,43<$F$12+$G$12),$E$12/$G$12,0) -> 0 | AY12: =IF(AND(44>=$F$12,44<$F$12+$G$12),$E$12/$G$12,0) -> 0 | AZ12: =IF(AND(45>=$F$12,45<$F$12+$G$12),$E$12/$G$12,0) -> 0 | BA12: =IF(AND(46>=$F$12,46<$F$12+$G$12),$E$12/$G$12,0) -> 0 | BB12: =IF(AND(47>=$F$12,47<$F$12+$G$12),$E$12/$G$12,0) -> 0 | BC12: =IF(AND(48>=$F$12,48<$F$12+$G$12),$E$12/$G$12,0) -> 0 | BD12: =IF(AND(49>=$F$12,49<$F$12+$G$12),$E$12/$G$12,0) -> 0 | BE12: =IF(AND(50>=$F$12,50<$F$12+$G$12),$E$12/$G$12,0) -> 0 | BF12: =IF(AND(51>=$F$12,51<$F$12+$G$12),$E$12/$G$12,0) -> 0 | BG12: =IF(AND(52>=$F$12,52<$F$12+$G$12),$E$12/$G$12,0) -> 0 | BH12: =IF(AND(53>=$F$12,53<$F$12+$G$12),$E$12/$G$12,0) -> 0 | BI12: =IF(AND(54>=$F$12,54<$F$12+$G$12),$E$12/$G$12,0) -> 0 | BJ12: =IF(AND(55>=$F$12,55<$F$12+$G$12),$E$12/$G$12,0) -> 0 | BK12: =IF(AND(56>=$F$12,56<$F$12+$G$12),$E$12/$G$12,0) -> 0 | BL12: =IF(AND(57>=$F$12,57<$F$12+$G$12),$E$12/$G$12,0) -> 0 | BM12: =IF(AND(58>=$F$12,58<$F$12+$G$12),$E$12/$G$12,0) -> 0 | BN12: =IF(AND(59>=$F$12,59<$F$12+$G$12),$E$12/$G$12,0) -> 0 | BO12: =IF(AND(60>=$F$12,60<$F$12+$G$12),$E$12/$G$12,0) -> 0
B13: TOTAL CAPEX | E13: =SUM(E5:E12) -> 150000 | H13: =SUM(H5:H12) -> 25000 | I13: =SUM(I5:I12) -> 25000 | J13: =SUM(J5:J12) -> 25000 | K13: =SUM(K5:K12) -> 25000 | L13: =SUM(L5:L12) -> 25000 | M13: =SUM(M5:M12) -> 25000 | N13: =SUM(N5:N12) -> 0 | O13: =SUM(O5:O12) -> 0 | ... BO13: =SUM(BO5:BO12) -> 0
A16: TENANT IMPROVEMENTS
A17: # | B17: Suite/Tenant | C17: SF | D17: Relet Month | E17: TI Cost ($) | H17: 1 | I17: 2 | J17: 3 | K17: 4 | L17: 5 | M17: 6 | N17: 7 | O17: 8 | P17: 9 | Q17: 10 | R17: 11 | S17: 12 | T17: 13 | U17: 14 | V17: 15 | W17: 16 | X17: 17 | Y17: 18 | Z17: 19 | AA17: 20 | AB17: 21 | AC17: 22 | AD17: 23 | AE17: 24 | AF17: 25 | AG17: 26 | AH17: 27 | AI17: 28 | AJ17: 29 | AK17: 30 | AL17: 31 | AM17: 32 | AN17: 33 | AO17: 34 | AP17: 35 | AQ17: 36 | AR17: 37 | AS17: 38 | AT17: 39 | AU17: 40 | AV17: 41 | AW17: 42 | AX17: 43 | AY17: 44 | AZ17: 45 | BA17: 46 | BB17: 47 | BC17: 48 | BD17: 49 | BE17: 50 | BF17: 51 | BG17: 52 | BH17: 53 | BI17: 54 | BJ17: 55 | BK17: 56 | BL17: 57 | BM17: 58 | BN17: 59 | BO17: 60
A18: ='Rent Roll'!A4 -> 4949 A1&A2 | B18: ='Rent Roll'!B4 -> Middle East Bakery | C18: ='Rent Roll'!C4 -> 2230 | D18: =IFERROR(MATCH("Relet", 'Rent Roll'!V4:CD4, 0), 0) -> 48 | E18: =('Rent Roll'!N4*'Rent Roll'!Q4+(1-'Rent Roll'!N4)*'Rent Roll'!P4)*'Rent Roll'!C4 -> 22300 | H18: =IF('Rent Roll'!V4="Relet",$E$18,0) -> 0 | I18: =IF(AND('Rent Roll'!W4="Relet",'Rent Roll'!V4<>"Relet"),$E$18,0) -> 0 | J18: =IF(AND('Rent Roll'!X4="Relet",'Rent Roll'!W4<>"Relet"),$E$18,0) -> 0 | K18: =IF(AND('Rent Roll'!Y4="Relet",'Rent Roll'!X4<>"Relet"),$E$18,0) -> 0 | L18: =IF(AND('Rent Roll'!Z4="Relet",'Rent Roll'!Y4<>"Relet"),$E$18,0) -> 0 | M18: =IF(AND('Rent Roll'!AA4="Relet",'Rent Roll'!Z4<>"Relet"),$E$18,0) -> 0 | N18: =IF(AND('Rent Roll'!AB4="Relet",'Rent Roll'!AA4<>"Relet"),$E$18,0) -> 0 | O18: =IF(AND('Rent Roll'!AC4="Relet",'Rent Roll'!AB4<>"Relet"),$E$18,0) -> 0 | P18: =IF(AND('Rent Roll'!AD4="Relet",'Rent Roll'!AC4<>"Relet"),$E$18,0) -> 0 | ... BO18: =IF(AND('Rent Roll'!CC4="Relet",'Rent Roll'!CB4<>"Relet"),$E$18,0) -> 0
A19: ='Rent Roll'!A7 -> 4949 B | B19: ='Rent Roll'!B7 -> VACANT | C19: ='Rent Roll'!C7 -> 910 | E19: =('Rent Roll'!N7*'Rent Roll'!Q7+(1-'Rent Roll'!N7)*'Rent Roll'!P7)*'Rent Roll'!C7 -> 22750 | H19: =IF('Rent Roll'!V7="Relet",$E$19,0) -> 0 | I19: =IF(AND('Rent Roll'!W7="Relet",'Rent Roll'!V7<>"Relet"),$E$19,0) -> 0 | J19: =IF(AND('Rent Roll'!X7="Relet",'Rent Roll'!W7<>"Relet"),$E$19,0) -> 0 | K19: =IF(AND('Rent Roll'!Y7="Relet",'Rent Roll'!X7<>"Relet"),$E$19,0) -> 0 | L19: =IF(AND('Rent Roll'!Z7="Relet",'Rent Roll'!Y7<>"Relet"),$E$19,0) -> 0 | M19: =IF(AND('Rent Roll'!AA7="Relet",'Rent Roll'!Z7<>"Relet"),$E$19,0) -> 22750 | N19: =IF(AND('Rent Roll'!AB7="Relet",'Rent Roll'!AA7<>"Relet"),$E$19,0) -> 0 | O19: =IF(AND('Rent Roll'!AC7="Relet",'Rent Roll'!AB7<>"Relet"),$E$19,0) -> 0 | P19: =IF(AND('Rent Roll'!AD7="Relet",'Rent Roll'!AC7<>"Relet"),$E$19,0) -> 0 | ... BO19: =IF(AND('Rent Roll'!CC7="Relet",'Rent Roll'!CB7<>"Relet"),$E$19,0) -> 0
A20: ='Rent Roll'!A10 -> 4949 C | B20: ='Rent Roll'!B10 -> Circle Pizza | C20: ='Rent Roll'!C10 -> 3620 | E20: =('Rent Roll'!N10*'Rent Roll'!Q10+(1-'Rent Roll'!N10)*'Rent Roll'!P10)*'Rent Roll'!C10 -> 36200 | H20: =IF('Rent Roll'!V10="Relet",$E$20,0) -> 0 | I20: =IF(AND('Rent Roll'!W10="Relet",'Rent Roll'!V10<>"Relet"),$E$20,0) -> 0 | J20: =IF(AND('Rent Roll'!X10="Relet",'Rent Roll'!W10<>"Relet"),$E$20,0) -> 0 | K20: =IF(AND('Rent Roll'!Y10="Relet",'Rent Roll'!X10<>"Relet"),$E$20,0) -> 0 | L20: =IF(AND('Rent Roll'!Z10="Relet",'Rent Roll'!Y10<>"Relet"),$E$20,0) -> 0 | M20: =IF(AND('Rent Roll'!AA10="Relet",'Rent Roll'!Z10<>"Relet"),$E$20,0) -> 0 | N20: =IF(AND('Rent Roll'!AB10="Relet",'Rent Roll'!AA10<>"Relet"),$E$20,0) -> 0 | O20: =IF(AND('Rent Roll'!AC10="Relet",'Rent Roll'!AB10<>"Relet"),$E$20,0) -> 0 | P20: =IF(AND('Rent Roll'!AD10="Relet",'Rent Roll'!AC10<>"Relet"),$E$20,0) -> 0 | ... BO20: =IF(AND('Rent Roll'!CC10="Relet",'Rent Roll'!CB10<>"Relet"),$E$20,0) -> 36200
A21: ='Rent Roll'!A13 -> 4949 D&E | B21: ='Rent Roll'!B13 -> Silver Sake | C21: ='Rent Roll'!C13 -> 1990 | E21: =('Rent Roll'!N13*'Rent Roll'!Q13+(1-'Rent Roll'!N13)*'Rent Roll'!P13)*'Rent Roll'!C13 -> 29850 | H21: =IF('Rent Roll'!V13="Relet",$E$21,0) -> 0 | I21: =IF(AND('Rent Roll'!W13="Relet",'Rent Roll'!V13<>"Relet"),$E$21,0) -> 0 | J21: =IF(AND('Rent Roll'!X13="Relet",'Rent Roll'!W13<>"Relet"),$E$21,0) -> 0 | K21: =IF(AND('Rent Roll'!Y13="Relet",'Rent Roll'!X13<>"Relet"),$E$21,0) -> 0 | L21: =IF(AND('Rent Roll'!Z13="Relet",'Rent Roll'!Y13<>"Relet"),$E$21,0) -> 0 | M21: =IF(AND('Rent Roll'!AA13="Relet",'Rent Roll'!Z13<>"Relet"),$E$21,0) -> 0 | N21: =IF(AND('Rent Roll'!AB13="Relet",'Rent Roll'!AA13<>"Relet"),$E$21,0) -> 29850 | O21: =IF(AND('Rent Roll'!AC13="Relet",'Rent Roll'!AB13<>"Relet"),$E$21,0) -> 0 | P21: =IF(AND('Rent Roll'!AD13="Relet",'Rent Roll'!AC13<>"Relet"),$E$21,0) -> 0 | ... BO21: =IF(AND('Rent Roll'!CC13="Relet",'Rent Roll'!CB13<>"Relet"),$E$21,0) -> 0
A22: ='Rent Roll'!A16 -> 4949 F | B22: ='Rent Roll'!B16 -> Waiel Merza | C22: ='Rent Roll'!C16 -> 810 | E22: =('Rent Roll'!N16*'Rent Roll'!Q16+(1-'Rent Roll'!N16)*'Rent Roll'!P16)*'Rent Roll'!C16 -> 8100 | H22: =IF('Rent Roll'!V16="Relet",$E$22,0) -> 0 | I22: =IF(AND('Rent Roll'!W16="Relet",'Rent Roll'!V16<>"Relet"),$E$22,0) -> 0 | J22: =IF(AND('Rent Roll'!X16="Relet",'Rent Roll'!W16<>"Relet"),$E$22,0) -> 0 | K22: =IF(AND('Rent Roll'!Y16="Relet",'Rent Roll'!X16<>"Relet"),$E$22,0) -> 0 | L22: =IF(AND('Rent Roll'!Z16="Relet",'Rent Roll'!Y16<>"Relet"),$E$22,0) -> 0 | M22: =IF(AND('Rent Roll'!AA16="Relet",'Rent Roll'!Z16<>"Relet"),$E$22,0) -> 0 | N22: =IF(AND('Rent Roll'!AB16="Relet",'Rent Roll'!AA16<>"Relet"),$E$22,0) -> 0 | O22: =IF(AND('Rent Roll'!AC16="Relet",'Rent Roll'!AB16<>"Relet"),$E$22,0) -> 0 | P22: =IF(AND('Rent Roll'!AD16="Relet",'Rent Roll'!AC16<>"Relet"),$E$22,0) -> 0 | ... BO22: =IF(AND('Rent Roll'!CC16="Relet",'Rent Roll'!CB16<>"Relet"),$E$22,0) -> 0
A23: ='Rent Roll'!A19 -> 4949 G | B23: ='Rent Roll'!B19 -> Cigarettes & Gifts | C23: ='Rent Roll'!C19 -> 810 | E23: =('Rent Roll'!N19*'Rent Roll'!Q19+(1-'Rent Roll'!N19)*'Rent Roll'!P19)*'Rent Roll'!C19 -> 8100 | H23: =IF('Rent Roll'!V19="Relet",$E$23,0) -> 0 | I23: =IF(AND('Rent Roll'!W19="Relet",'Rent Roll'!V19<>"Relet"),$E$23,0) -> 0 | J23: =IF(AND('Rent Roll'!X19="Relet",'Rent Roll'!W19<>"Relet"),$E$23,0) -> 0 | K23: =IF(AND('Rent Roll'!Y19="Relet",'Rent Roll'!X19<>"Relet"),$E$23,0) -> 0 | L23: =IF(AND('Rent Roll'!Z19="Relet",'Rent Roll'!Y19<>"Relet"),$E$23,0) -> 0 | M23: =IF(AND('Rent Roll'!AA19="Relet",'Rent Roll'!Z19<>"Relet"),$E$23,0) -> 0 | N23: =IF(AND('Rent Roll'!AB19="Relet",'Rent Roll'!AA19<>"Relet"),$E$23,0) -> 8100 | O23: =IF(AND('Rent Roll'!AC19="Relet",'Rent Roll'!AB19<>"Relet"),$E$23,0) -> 0 | P23: =IF(AND('Rent Roll'!AD19="Relet",'Rent Roll'!AC19<>"Relet"),$E$23,0) -> 0 | ... BO23: =IF(AND('Rent Roll'!CC19="Relet",'Rent Roll'!CB19<>"Relet"),$E$23,0) -> 0
A24: ='Rent Roll'!A22 -> 4949 H | B24: ='Rent Roll'!B22 -> Brittany Hair & Nails | C24: ='Rent Roll'!C22 -> 810 | E24: =('Rent Roll'!N22*'Rent Roll'!Q22+(1-'Rent Roll'!N22)*'Rent Roll'!P22)*'Rent Roll'!C22 -> 8100 | H24: =IF('Rent Roll'!V22="Relet",$E$24,0) -> 0 | I24: =IF(AND('Rent Roll'!W22="Relet",'Rent Roll'!V22<>"Relet"),$E$24,0) -> 0 | J24: =IF(AND('Rent Roll'!X22="Relet",'Rent Roll'!W22<>"Relet"),$E$24,0) -> 0 | K24: =IF(AND('Rent Roll'!Y22="Relet",'Rent Roll'!X22<>"Relet"),$E$24,0) -> 0 | L24: =IF(AND('Rent Roll'!Z22="Relet",'Rent Roll'!Y22<>"Relet"),$E$24,0) -> 0 | M24: =IF(AND('Rent Roll'!AA22="Relet",'Rent Roll'!Z22<>"Relet"),$E$24,0) -> 0 | N24: =IF(AND('Rent Roll'!AB22="Relet",'Rent Roll'!AA22<>"Relet"),$E$24,0) -> 8100 | O24: =IF(AND('Rent Roll'!AC22="Relet",'Rent Roll'!AB22<>"Relet"),$E$24,0) -> 0 | P24: =IF(AND('Rent Roll'!AD22="Relet",'Rent Roll'!AC22<>"Relet"),$E$24,0) -> 0 | ... BO24: =IF(AND('Rent Roll'!CC22="Relet",'Rent Roll'!CB22<>"Relet"),$E$24,0) -> 0
A25: ='Rent Roll'!A25 -> 4949 I | B25: ='Rent Roll'!B25 -> Madeville Hair Salon | C25: ='Rent Roll'!C25 -> 810 | E25: =('Rent Roll'!N25*'Rent Roll'!Q25+(1-'Rent Roll'!N25)*'Rent Roll'!P25)*'Rent Roll'!C25 -> 12150 | H25: =IF('Rent Roll'!V25="Relet",$E$25,0) -> 0 | I25: =IF(AND('Rent Roll'!W25="Relet",'Rent Roll'!V25<>"Relet"),$E$25,0) -> 0 | J25: =IF(AND('Rent Roll'!X25="Relet",'Rent Roll'!W25<>"Relet"),$E$25,0) -> 0 | K25: =IF(AND('Rent Roll'!Y25="Relet",'Rent Roll'!X25<>"Relet"),$E$25,0) -> 0 | L25: =IF(AND('Rent Roll'!Z25="Relet",'Rent Roll'!Y25<>"Relet"),$E$25,0) -> 0 | M25: =IF(AND('Rent Roll'!AA25="Relet",'Rent Roll'!Z25<>"Relet"),$E$25,0) -> 0 | N25: =IF(AND('Rent Roll'!AB25="Relet",'Rent Roll'!AA25<>"Relet"),$E$25,0) -> 12150 | O25: =IF(AND('Rent Roll'!AC25="Relet",'Rent Roll'!AB25<>"Relet"),$E$25,0) -> 0 | P25: =IF(AND('Rent Roll'!AD25="Relet",'Rent Roll'!AC25<>"Relet"),$E$25,0) -> 0 | ... BO25: =IF(AND('Rent Roll'!CC25="Relet",'Rent Roll'!CB25<>"Relet"),$E$25,0) -> 0
A26: ='Rent Roll'!A28 -> 4949 J | B26: ='Rent Roll'!B28 -> VACANT | C26: ='Rent Roll'!C28 -> 1350 | E26: =('Rent Roll'!N28*'Rent Roll'!Q28+(1-'Rent Roll'!N28)*'Rent Roll'!P28)*'Rent Roll'!C28 -> 33750 | H26: =IF('Rent Roll'!V28="Relet",$E$26,0) -> 0 | I26: =IF(AND('Rent Roll'!W28="Relet",'Rent Roll'!V28<>"Relet"),$E$26,0) -> 0 | J26: =IF(AND('Rent Roll'!X28="Relet",'Rent Roll'!W28<>"Relet"),$E$26,0) -> 0 | K26: =IF(AND('Rent Roll'!Y28="Relet",'Rent Roll'!X28<>"Relet"),$E$26,0) -> 0 | L26: =IF(AND('Rent Roll'!Z28="Relet",'Rent Roll'!Y28<>"Relet"),$E$26,0) -> 0 | M26: =IF(AND('Rent Roll'!AA28="Relet",'Rent Roll'!Z28<>"Relet"),$E$26,0) -> 33750 | N26: =IF(AND('Rent Roll'!AB28="Relet",'Rent Roll'!AA28<>"Relet"),$E$26,0) -> 0 | O26: =IF(AND('Rent Roll'!AC28="Relet",'Rent Roll'!AB28<>"Relet"),$E$26,0) -> 0 | P26: =IF(AND('Rent Roll'!AD28="Relet",'Rent Roll'!AC28<>"Relet"),$E$26,0) -> 0 | ... BO26: =IF(AND('Rent Roll'!CC28="Relet",'Rent Roll'!CB28<>"Relet"),$E$26,0) -> 0
A27: ='Rent Roll'!A31 -> 4955 A | B27: ='Rent Roll'!B31 -> Sharing & Caring | C27: ='Rent Roll'!C31 -> 1350 | E27: =('Rent Roll'!N31*'Rent Roll'!Q31+(1-'Rent Roll'!N31)*'Rent Roll'!P31)*'Rent Roll'!C31 -> 20250 | H27: =IF('Rent Roll'!V31="Relet",$E$27,0) -> 0 | I27: =IF(AND('Rent Roll'!W31="Relet",'Rent Roll'!V31<>"Relet"),$E$27,0) -> 0 | J27: =IF(AND('Rent Roll'!X31="Relet",'Rent Roll'!W31<>"Relet"),$E$27,0) -> 0 | K27: =IF(AND('Rent Roll'!Y31="Relet",'Rent Roll'!X31<>"Relet"),$E$27,0) -> 0 | L27: =IF(AND('Rent Roll'!Z31="Relet",'Rent Roll'!Y31<>"Relet"),$E$27,0) -> 0 | M27: =IF(AND('Rent Roll'!AA31="Relet",'Rent Roll'!Z31<>"Relet"),$E$27,0) -> 0 | N27: =IF(AND('Rent Roll'!AB31="Relet",'Rent Roll'!AA31<>"Relet"),$E$27,0) -> 20250 | O27: =IF(AND('Rent Roll'!AC31="Relet",'Rent Roll'!AB31<>"Relet"),$E$27,0) -> 0 | P27: =IF(AND('Rent Roll'!AD31="Relet",'Rent Roll'!AC31<>"Relet"),$E$27,0) -> 0 | ... BO27: =IF(AND('Rent Roll'!CC31="Relet",'Rent Roll'!CB31<>"Relet"),$E$27,0) -> 0
A28: ='Rent Roll'!A34 -> 4955 B | B28: ='Rent Roll'!B34 -> Spoteless Cleaners | C28: ='Rent Roll'!C34 -> 1310 | E28: =('Rent Roll'!N34*'Rent Roll'!Q34+(1-'Rent Roll'!N34)*'Rent Roll'!P34)*'Rent Roll'!C34 -> 19650 | H28: =IF('Rent Roll'!V34="Relet",$E$28,0) -> 0 | I28: =IF(AND('Rent Roll'!W34="Relet",'Rent Roll'!V34<>"Relet"),$E$28,0) -> 0 | J28: =IF(AND('Rent Roll'!X34="Relet",'Rent Roll'!W34<>"Relet"),$E$28,0) -> 0 | K28: =IF(AND('Rent Roll'!Y34="Relet",'Rent Roll'!X34<>"Relet"),$E$28,0) -> 0 | L28: =IF(AND('Rent Roll'!Z34="Relet",'Rent Roll'!Y34<>"Relet"),$E$28,0) -> 0 | M28: =IF(AND('Rent Roll'!AA34="Relet",'Rent Roll'!Z34<>"Relet"),$E$28,0) -> 0 | N28: =IF(AND('Rent Roll'!AB34="Relet",'Rent Roll'!AA34<>"Relet"),$E$28,0) -> 19650 | O28: =IF(AND('Rent Roll'!AC34="Relet",'Rent Roll'!AB34<>"Relet"),$E$28,0) -> 0 | P28: =IF(AND('Rent Roll'!AD34="Relet",'Rent Roll'!AC34<>"Relet"),$E$28,0) -> 0 | ... BO28: =IF(AND('Rent Roll'!CC34="Relet",'Rent Roll'!CB34<>"Relet"),$E$28,0) -> 0
A29: ='Rent Roll'!A37 -> 4955 C | B29: ='Rent Roll'!B37 -> Dawn's Pet Palace | C29: ='Rent Roll'!C37 -> 1880 | E29: =('Rent Roll'!N37*'Rent Roll'!Q37+(1-'Rent Roll'!N37)*'Rent Roll'!P37)*'Rent Roll'!C37 -> 18800 | H29: =IF('Rent Roll'!V37="Relet",$E$29,0) -> 0 | I29: =IF(AND('Rent Roll'!W37="Relet",'Rent Roll'!V37<>"Relet"),$E$29,0) -> 0 | J29: =IF(AND('Rent Roll'!X37="Relet",'Rent Roll'!W37<>"Relet"),$E$29,0) -> 0 | K29: =IF(AND('Rent Roll'!Y37="Relet",'Rent Roll'!X37<>"Relet"),$E$29,0) -> 0 | L29: =IF(AND('Rent Roll'!Z37="Relet",'Rent Roll'!Y37<>"Relet"),$E$29,0) -> 0 | M29: =IF(AND('Rent Roll'!AA37="Relet",'Rent Roll'!Z37<>"Relet"),$E$29,0) -> 0 | N29: =IF(AND('Rent Roll'!AB37="Relet",'Rent Roll'!AA37<>"Relet"),$E$29,0) -> 0 | O29: =IF(AND('Rent Roll'!AC37="Relet",'Rent Roll'!AB37<>"Relet"),$E$29,0) -> 0 | P29: =IF(AND('Rent Roll'!AD37="Relet",'Rent Roll'!AC37<>"Relet"),$E$29,0) -> 0 | ... BO29: =IF(AND('Rent Roll'!CC37="Relet",'Rent Roll'!CB37<>"Relet"),$E$29,0) -> 0
